Workbook

Sheet Portada
F11: Reporte mensual de avance de indicadores | G11: 2025
F12: ABRIL - 2025
F15: Departamento de Planificación y Control de Gestión
F16: División de Planificación y Presupuesto
F18: Subsecretaría de Educación

Sheet 01-PANEL
J2: SUBSECRETARÍA DE EDUCACIÓN
J4: ESTADO RIESGO INDICADORES
J5: POR INSTRUMENTO DE GESTIÓN | N5: ABRIL - 2025
C8: =_xlfn.CONCAT("PERIODO ", N5) -> PERIODO ABRIL - 2025 | G8: TIPO | K8: RIESGO BAJO | M8: RIESGO MEDIO | O8: RIESGO ALTO | R8: TOTAL INDICADORES
C10: TOTAL INDICADORES | G10: CDC NIVEL CENTRAL | K10: 34 | M10: 0 | O10: 0 | R10: =SUM($K10:$O10) -> 34
C11: PMG | D11: =R13 -> 6 | G11: CDC REGIONES | K11: 78 | M11: 0 | O11: 0 | R11: =SUM($K11:$O11) -> 78
C12: H | D12: =R12 -> 4 | G12: H | K12: 4 | M12: 0 | O12: 0 | R12: =SUM($K12:$O12) -> 4
C13: CDC NIVEL CENTRAL | D13: =R10 -> 34 | G13: PMG | K13: 6 | M13: 0 | O13: 0 | R13: =SUM($K13:$O13) -> 6
C14: CDC REGIONES | D14: =R11 -> 78 | G14: TOTAL | K14: =SUM(K10:K13) -> 122 | M14: =SUM(M10:M13) -> 0 | O14: =SUM(O10:O13) -> 0 | R14: =SUM(R10:R13) -> 122
C15: Total general | D15: =R14 -> 122
C24: INDICADORES CON RIESGO
C25: PMG | D25: =SUM(M13:O13) -> 0
C26: H | D26: =SUM(M12:O12) -> 0
C27: CDC NIVEL CENTRAL | D27: =SUM(M10:O10) -> 0
C28: CDC REGIONES | D28: =SUM(M11:O11) -> 0
C29: Total general | D29: =SUM(M14:O14) -> 0

Sheet data_panel
B3: PMG | C3: Bajo | D3: Medio | E3: Alto
B4: DAG | C4: 2 | D4: 0 | E4: 0
B5: DIPLAP | C5: 2 | D5: 0 | E5: 0
B6: Gab Subse | C6: 2 | D6: 0 | E6: 0
B8: CPEIP | C8: 1 | D8: 0 | E8: 0
B9: DEG | C9: 1 | D9: 0 | E9: 0
B10: UCE | C10: 2 | D10: 0 | E10: 0
B13: CPEIP | C13: 3 | D13: 0 | E13: 0
B14: DAG | C14: 4 | D14: 0 | E14: 0
B15: DEG | C15: 3 | D15: 0 | E15: 0
B16: Jurídica | C16: 7 | D16: 0 | E16: 0
B17: DIPLAP | C17: 6 | D17: 0 | E17: 0
B18: Gab Ministro | C18: 3 | D18: 0 | E18: 0
... B20: UCE | C20: 5 | D20: 0 | E20: 0
B24: CDC | C24: Bajo | D24: Medio | E24: Alto
B25: Antofagasta | C25: 5 | D25: 0 | E25: 0
B26: Arica y Parinacota | C26: 5 | D26: 0 | E26: 0
B27: Atacama | C27: 5 | D27: 0 | E27: 0
B28: Aysén | C28: 5 | D28: 0 | E28: 0
B29: Biobío | C29: 5 | D29: 0 | E29: 0
B30: Coquimbo | C30: 5 | D30: 0 | E30: 0
B31: La Araucanía | C31: 5 | D31: 0 | E31: 0
B32: Los Lagos | C32: 5 | D32: 0 | E32: 0
B33: Los Ríos | C33: 5 | D33: 0 | E33: 0
B34: Magallanes | C34: 5 | D34: 0 | E34: 0
B35: Maule | C35: 5 | D35: 0 | E35: 0
B36: Metropolitana | C36: 4 | D36: 0 | E36: 0
... B40: Ñuble | C40: 4 | D40: 0 | E40: 0

Sheet 02-ESTADO NC
A2: NIVEL CENTRAL: ESTADO DE RIESGO INDICADORES POR CR AL CIERRE DE | T2: ABRIL - 2025

Sheet 03-  ESTADO REGIONES
A1: REGIONES : ESTADO RIESGO INDICADORES POR CR AL CIERRE:
A2: ABRIL - 2025
B5: REGIÓN | C5: CDC: Acciones del plan regional ejecutadas | F5: CDC: solicitudes de certificados de estudio no disponibles en línea | I5: CDC: Acciones del plan fortalecimineto de la matrícula implementadas | L5: CDC: capacitaciones a sostenedores | O5: CDC: Estudiantes OAP que postulan a través del SAE
B6: Tarapacá | D6: =IF(data_status_reg!$E4="bajo",0,IF(data_status_reg!$E4="medio",0.5,IF(data_status_reg!$E4="alto",1,"falta riesgo"))) -> 0 | G6: =IF(data_status_reg!$E20="bajo",0,IF(data_status_reg!$E20="medio",0.5,IF(data_status_reg!$E20="alto",1,"falta riesgo"))) -> 0 | J6: =IF(data_status_reg!$E36="bajo",0,IF(data_status_reg!$E36="medio",0.5,IF(data_status_reg!$E36="alto",1,"falta riesgo"))) -> 0 | M6: =IF(data_status_reg!$E52="bajo",0,IF(data_status_reg!$E52="medio",0.5,IF(data_status_reg!$E52="alto",1,"falta riesgo"))) -> 0 | P6: =IF(data_status_reg!$E68="bajo",0,IF(data_status_reg!$E68="medio",0.5,IF(data_status_reg!$E68="alto",1,"falta riesgo"))) -> 0
B7: Antofagasta | D7: =IF(data_status_reg!$E5="bajo",0,IF(data_status_reg!$E5="medio",0.5,IF(data_status_reg!$E5="alto",1,"falta riesgo"))) -> 0 | G7: =IF(data_status_reg!$E21="bajo",0,IF(data_status_reg!$E21="medio",0.5,IF(data_status_reg!$E21="alto",1,"falta riesgo"))) -> 0 | J7: =IF(data_status_reg!$E37="bajo",0,IF(data_status_reg!$E37="medio",0.5,IF(data_status_reg!$E37="alto",1,"falta riesgo"))) -> 0 | M7: =IF(data_status_reg!$E53="bajo",0,IF(data_status_reg!$E53="medio",0.5,IF(data_status_reg!$E53="alto",1,"falta riesgo"))) -> 0 | P7: =IF(data_status_reg!$E69="bajo",0,IF(data_status_reg!$E69="medio",0.5,IF(data_status_reg!$E69="alto",1,"falta riesgo"))) -> 0
B8: Atacama | D8: =IF(data_status_reg!$E6="bajo",0,IF(data_status_reg!$E6="medio",0.5,IF(data_status_reg!$E6="alto",1,"falta riesgo"))) -> 0 | G8: =IF(data_status_reg!$E22="bajo",0,IF(data_status_reg!$E22="medio",0.5,IF(data_status_reg!$E22="alto",1,"falta riesgo"))) -> 0 | J8: =IF(data_status_reg!$E38="bajo",0,IF(data_status_reg!$E38="medio",0.5,IF(data_status_reg!$E38="alto",1,"falta riesgo"))) -> 0 | M8: =IF(data_status_reg!$E54="bajo",0,IF(data_status_reg!$E54="medio",0.5,IF(data_status_reg!$E54="alto",1,"falta riesgo"))) -> 0 | P8: =IF(data_status_reg!$E70="bajo",0,IF(data_status_reg!$E70="medio",0.5,IF(data_status_reg!$E70="alto",1,"falta riesgo"))) -> 0
B9: Coquimbo | D9: =IF(data_status_reg!$E7="bajo",0,IF(data_status_reg!$E7="medio",0.5,IF(data_status_reg!$E7="alto",1,"falta riesgo"))) -> 0 | G9: =IF(data_status_reg!$E23="bajo",0,IF(data_status_reg!$E23="medio",0.5,IF(data_status_reg!$E23="alto",1,"falta riesgo"))) -> 0 | J9: =IF(data_status_reg!$E39="bajo",0,IF(data_status_reg!$E39="medio",0.5,IF(data_status_reg!$E39="alto",1,"falta riesgo"))) -> 0 | M9: =IF(data_status_reg!$E55="bajo",0,IF(data_status_reg!$E55="medio",0.5,IF(data_status_reg!$E55="alto",1,"falta riesgo"))) -> 0 | P9: =IF(data_status_reg!$E71="bajo",0,IF(data_status_reg!$E71="medio",0.5,IF(data_status_reg!$E71="alto",1,"falta riesgo"))) -> 0
B10: Valparaíso | D10: =IF(data_status_reg!$E8="bajo",0,IF(data_status_reg!$E8="medio",0.5,IF(data_status_reg!$E8="alto",1,"falta riesgo"))) -> 0 | G10: =IF(data_status_reg!$E24="bajo",0,IF(data_status_reg!$E24="medio",0.5,IF(data_status_reg!$E24="alto",1,"falta riesgo"))) -> 0 | J10: =IF(data_status_reg!$E40="bajo",0,IF(data_status_reg!$E40="medio",0.5,IF(data_status_reg!$E40="alto",1,"falta riesgo"))) -> 0 | M10: =IF(data_status_reg!$E56="bajo",0,IF(data_status_reg!$E56="medio",0.5,IF(data_status_reg!$E56="alto",1,"falta riesgo"))) -> 0 | P10: =IF(data_status_reg!$E72="bajo",0,IF(data_status_reg!$E72="medio",0.5,IF(data_status_reg!$E72="alto",1,"falta riesgo"))) -> 0
B11: O'Higgins | D11: =IF(data_status_reg!$E9="bajo",0,IF(data_status_reg!$E9="medio",0.5,IF(data_status_reg!$E9="alto",1,"falta riesgo"))) -> 0 | G11: =IF(data_status_reg!$E25="bajo",0,IF(data_status_reg!$E25="medio",0.5,IF(data_status_reg!$E25="alto",1,"falta riesgo"))) -> 0 | J11: =IF(data_status_reg!$E41="bajo",0,IF(data_status_reg!$E41="medio",0.5,IF(data_status_reg!$E41="alto",1,"falta riesgo"))) -> 0 | M11: =IF(data_status_reg!$E57="bajo",0,IF(data_status_reg!$E57="medio",0.5,IF(data_status_reg!$E57="alto",1,"falta riesgo"))) -> 0 | P11: =IF(data_status_reg!$E73="bajo",0,IF(data_status_reg!$E73="medio",0.5,IF(data_status_reg!$E73="alto",1,"falta riesgo"))) -> 0
B12: Maule | D12: =IF(data_status_reg!$E10="bajo",0,IF(data_status_reg!$E10="medio",0.5,IF(data_status_reg!$E10="alto",1,"falta riesgo"))) -> 0 | G12: =IF(data_status_reg!$E26="bajo",0,IF(data_status_reg!$E26="medio",0.5,IF(data_status_reg!$E26="alto",1,"falta riesgo"))) -> 0 | J12: =IF(data_status_reg!$E42="bajo",0,IF(data_status_reg!$E42="medio",0.5,IF(data_status_reg!$E42="alto",1,"falta riesgo"))) -> 0 | M12: =IF(data_status_reg!$E58="bajo",0,IF(data_status_reg!$E58="medio",0.5,IF(data_status_reg!$E58="alto",1,"falta riesgo"))) -> 0 | P12: =IF(data_status_reg!$E74="bajo",0,IF(data_status_reg!$E74="medio",0.5,IF(data_status_reg!$E74="alto",1,"falta riesgo"))) -> 0
B13: Biobío | D13: =IF(data_status_reg!$E11="bajo",0,IF(data_status_reg!$E11="medio",0.5,IF(data_status_reg!$E11="alto",1,"falta riesgo"))) -> 0 | G13: =IF(data_status_reg!$E27="bajo",0,IF(data_status_reg!$E27="medio",0.5,IF(data_status_reg!$E27="alto",1,"falta riesgo"))) -> 0 | J13: =IF(data_status_reg!$E43="bajo",0,IF(data_status_reg!$E43="medio",0.5,IF(data_status_reg!$E43="alto",1,"falta riesgo"))) -> 0 | M13: =IF(data_status_reg!$E59="bajo",0,IF(data_status_reg!$E59="medio",0.5,IF(data_status_reg!$E59="alto",1,"falta riesgo"))) -> 0 | P13: =IF(data_status_reg!$E75="bajo",0,IF(data_status_reg!$E75="medio",0.5,IF(data_status_reg!$E75="alto",1,"falta riesgo"))) -> 0
B14: Araucanía | D14: =IF(data_status_reg!$E12="bajo",0,IF(data_status_reg!$E12="medio",0.5,IF(data_status_reg!$E12="alto",1,"falta riesgo"))) -> 0 | G14: =IF(data_status_reg!$E28="bajo",0,IF(data_status_reg!$E28="medio",0.5,IF(data_status_reg!$E28="alto",1,"falta riesgo"))) -> 0 | J14: =IF(data_status_reg!$E44="bajo",0,IF(data_status_reg!$E44="medio",0.5,IF(data_status_reg!$E44="alto",1,"falta riesgo"))) -> 0 | M14: =IF(data_status_reg!$E60="bajo",0,IF(data_status_reg!$E60="medio",0.5,IF(data_status_reg!$E60="alto",1,"falta riesgo"))) -> 0 | P14: =IF(data_status_reg!$E76="bajo",0,IF(data_status_reg!$E76="medio",0.5,IF(data_status_reg!$E76="alto",1,"falta riesgo"))) -> 0
B15: Los Lagos | D15: =IF(data_status_reg!$E13="bajo",0,IF(data_status_reg!$E13="medio",0.5,IF(data_status_reg!$E13="alto",1,"falta riesgo"))) -> 0 | G15: =IF(data_status_reg!$E29="bajo",0,IF(data_status_reg!$E29="medio",0.5,IF(data_status_reg!$E29="alto",1,"falta riesgo"))) -> 0 | J15: =IF(data_status_reg!$E45="bajo",0,IF(data_status_reg!$E45="medio",0.5,IF(data_status_reg!$E45="alto",1,"falta riesgo"))) -> 0 | M15: =IF(data_status_reg!$E61="bajo",0,IF(data_status_reg!$E61="medio",0.5,IF(data_status_reg!$E61="alto",1,"falta riesgo"))) -> 0 | P15: =IF(data_status_reg!$E77="bajo",0,IF(data_status_reg!$E77="medio",0.5,IF(data_status_reg!$E77="alto",1,"falta riesgo"))) -> 0
B16: Aysén | D16: =IF(data_status_reg!$E14="bajo",0,IF(data_status_reg!$E14="medio",0.5,IF(data_status_reg!$E14="alto",1,"falta riesgo"))) -> 0 | G16: =IF(data_status_reg!$E30="bajo",0,IF(data_status_reg!$E30="medio",0.5,IF(data_status_reg!$E30="alto",1,"falta riesgo"))) -> 0 | J16: =IF(data_status_reg!$E46="bajo",0,IF(data_status_reg!$E46="medio",0.5,IF(data_status_reg!$E46="alto",1,"falta riesgo"))) -> 0 | M16: =IF(data_status_reg!$E62="bajo",0,IF(data_status_reg!$E62="medio",0.5,IF(data_status_reg!$E62="alto",1,"falta riesgo"))) -> 0 | P16: =IF(data_status_reg!$E78="bajo",0,IF(data_status_reg!$E78="medio",0.5,IF(data_status_reg!$E78="alto",1,"falta riesgo"))) -> 0
B17: Magallanes | D17: =IF(data_status_reg!$E15="bajo",0,IF(data_status_reg!$E15="medio",0.5,IF(data_status_reg!$E15="alto",1,"falta riesgo"))) -> 0 | G17: =IF(data_status_reg!$E31="bajo",0,IF(data_status_reg!$E31="medio",0.5,IF(data_status_reg!$E31="alto",1,"falta riesgo"))) -> 0 | J17: =IF(data_status_reg!$E47="bajo",0,IF(data_status_reg!$E47="medio",0.5,IF(data_status_reg!$E47="alto",1,"falta riesgo"))) -> 0 | M17: =IF(data_status_reg!$E63="bajo",0,IF(data_status_reg!$E63="medio",0.5,IF(data_status_reg!$E63="alto",1,"falta riesgo"))) -> 0 | P17: =IF(data_status_reg!$E79="bajo",0,IF(data_status_reg!$E79="medio",0.5,IF(data_status_reg!$E79="alto",1,"falta riesgo"))) -> 0
B18: Metropolitana | D18: =IF(data_status_reg!$E16="bajo",0,IF(data_status_reg!$E16="medio",0.5,IF(data_status_reg!$E16="alto",1,"falta riesgo"))) -> 0 | G18: No aplica | J18: =IF(data_status_reg!$E48="bajo",0,IF(data_status_reg!$E48="medio",0.5,IF(data_status_reg!$E48="alto",1,"falta riesgo"))) -> 0 | M18: =IF(data_status_reg!$E64="bajo",0,IF(data_status_reg!$E64="medio",0.5,IF(data_status_reg!$E64="alto",1,"falta riesgo"))) -> 0 | P18: =IF(data_status_reg!$E80="bajo",0,IF(data_status_reg!$E80="medio",0.5,IF(data_status_reg!$E80="alto",1,"falta riesgo"))) -> 0
B19: Los Ríos | D19: =IF(data_status_reg!$E17="bajo",0,IF(data_status_reg!$E17="medio",0.5,IF(data_status_reg!$E17="alto",1,"falta riesgo"))) -> 0 | G19: =IF(data_status_reg!$E33="bajo",0,IF(data_status_reg!$E33="medio",0.5,IF(data_status_reg!$E33="alto",1,"falta riesgo"))) -> 0 | J19: =IF(data_status_reg!$E49="bajo",0,IF(data_status_reg!$E49="medio",0.5,IF(data_status_reg!$E49="alto",1,"falta riesgo"))) -> 0 | M19: =IF(data_status_reg!$E65="bajo",0,IF(data_status_reg!$E65="medio",0.5,IF(data_status_reg!$E65="alto",1,"falta riesgo"))) -> 0 | P19: =IF(data_status_reg!$E81="bajo",0,IF(data_status_reg!$E81="medio",0.5,IF(data_status_reg!$E81="alto",1,"falta riesgo"))) -> 0
B20: Arica y Parinacota | D20: =IF(data_status_reg!$E18="bajo",0,IF(data_status_reg!$E18="medio",0.5,IF(data_status_reg!$E18="alto",1,"falta riesgo"))) -> 0 | G20: =IF(data_status_reg!$E34="bajo",0,IF(data_status_reg!$E34="medio",0.5,IF(data_status_reg!$E34="alto",1,"falta riesgo"))) -> 0 | J20: =IF(data_status_reg!$E50="bajo",0,IF(data_status_reg!$E50="medio",0.5,IF(data_status_reg!$E50="alto",1,"falta riesgo"))) -> 0 | M20: =IF(data_status_reg!$E66="bajo",0,IF(data_status_reg!$E66="medio",0.5,IF(data_status_reg!$E66="alto",1,"falta riesgo"))) -> 0 | P20: =IF(data_status_reg!$E82="bajo",0,IF(data_status_reg!$E82="medio",0.5,IF(data_status_reg!$E82="alto",1,"falta riesgo"))) -> 0
B21: Ñuble | D21: =IF(data_status_reg!$E19="bajo",0,IF(data_status_reg!$E19="medio",0.5,IF(data_status_reg!$E19="alto",1,"falta riesgo"))) -> 0 | G21: No aplica | J21: =IF(data_status_reg!$E51="bajo",0,IF(data_status_reg!$E51="medio",0.5,IF(data_status_reg!$E51="alto",1,"falta riesgo"))) -> 0 | M21: =IF(data_status_reg!$E67="bajo",0,IF(data_status_reg!$E67="medio",0.5,IF(data_status_reg!$E67="alto",1,"falta riesgo"))) -> 0 | P21: =IF(data_status_reg!$E83="bajo",0,IF(data_status_reg!$E83="medio",0.5,IF(data_status_reg!$E83="alto",1,"falta riesgo"))) -> 0

Sheet data_status_NC
I1: Variable | J1: Valor Informe Mes
A2: Gabinete Ministro
C3: CDC: Solicitudes de información respondidas | D3: =IF(J5="bajo",0,IF(J5="medio",0.5,IF(J5="alto",1,"falta riesgo"))) -> 0 | I3: I16_002-Gabinete Ministerio | J3: Bajo
C4: CDC: Documentos publicados en web Centro de Estudios | D4: =IF(J4="bajo",0,IF(J4="medio",0.5,IF(J4="alto",1,"falta riesgo"))) -> 0 | I4: I20_013-Gabinete Ministerio | J4: Bajo
C5: CDC: Auditorías del Plan Anual de Auditoría | D5: =IF(J3="bajo",0,IF(J3="medio",0.5,IF(J3="alto",1,"falta riesgo"))) -> 0 | I5: I20_014-Gabinete Ministerio | J5: Bajo
I6: I16_002-Gabinete Ministerio | J6: Bajo
A7: Gabinete Subsecretaria | C7: CDC: Solicitudes de certificados de estudio | D7: =IF(J9="bajo",0,IF(J9="medio",0.5,IF(J9="alto",1,"falta riesgo"))) -> 0 | I7: I20_013-Gabinete Ministerio | J7: Bajo
C8: CDC: Acciones formativas del Centro de Innovación | D8: =IF(J14="bajo",0,IF(J14="medio",0.5,IF(J14="alto",1,"falta riesgo"))) -> 0 | I8: I20_014-Gabinete Ministerio | J8: Bajo
C9: CDC: Compra de equipamiento | D9: =IF(J15="bajo",0,IF(J15="medio",0.5,IF(J15="alto",1,"falta riesgo"))) -> 0 | I9: I19_026-Gabinete Subsecretaría | J9: Bajo
C10: PMG: Sistema Calidad de Servicio y Experiencia | D10: =IF(J10="bajo",0,IF(J10="medio",0.5,IF(J10="alto",1,"falta riesgo"))) -> 0 | I10: I23_015-Gabinete Subsecretaría | J10: Bajo
C11: H: Kit material Educación No Sexista | D11: =IF(J12="bajo",0,IF(J12="medio",0.5,IF(J12="alto",1,"falta riesgo"))) -> 0 | I11: I21_001-Gabinete Subsecretaría | J11: Bajo
C12: H: Servicio de conectividad a internet | D12: =IF(J13="bajo",0,IF(J13="medio",0.5,IF(J13="alto",1,"falta riesgo"))) -> 0 | I12: I24_001-Gabinete Subsecretaría | J12: Bajo
C13: PMG: Medidas de Equidad de Género | D13: =IF(J11="bajo",0,IF(J11="medio",0.5,IF(J11="alto",1,"falta riesgo"))) -> 0 | I13: I24_002-Gabinete Subsecretaría | J13: Bajo
I14: I25_002-CPEIP | J14: Bajo
A15: CPEIP | C15: CDC: Formación inicial docente | D15: =IF(J18="bajo",0,IF(J18="medio",0.5,IF(J18="alto",1,"falta riesgo"))) -> 0 | I15: I23_018-CPEIP | J15: Bajo
C16: CDC: Diseño de ofertas formativas | D16: =IF(J17="bajo",0,IF(J17="medio",0.5,IF(J17="alto",1,"falta riesgo"))) -> 0 | I16: I25_003-CPEIP | J16: Bajo
C17: CDC: Diseño de modelos de inducción docente | D17: =IF(J19="bajo",0,IF(J19="medio",0.5,IF(J19="alto",1,"falta riesgo"))) -> 0 | I17: I25_001-CPEIP | J17: Bajo
C18: H: Provincias que participan de acciones de CPEIP | D18: =IF(J16="bajo",0,IF(J16="medio",0.5,IF(J16="alto",1,"falta riesgo"))) -> 0 | I18: I25_011-DEG | J18: Bajo
I19: I17_001-DEG | J19: Bajo
A20: DEG | C20: CDC: Inscipción para completar los estudios | D20: =IF(J22="bajo",0,IF(J22="medio",0.5,IF(J22="alto",1,"falta riesgo"))) -> 0 | I20: I23_004-DEG | J20: Bajo
C21: CDC: Acciones plan de difusión | D21: =IF(J24="bajo",0,IF(J24="medio",0.5,IF(J24="alto",1,"falta riesgo"))) -> 0 | I21: I24_009-DEG | J21: Bajo
C22: CDC: Procesos de validación de estudios | D22: =IF(J23="bajo",0,IF(J23="medio",0.5,IF(J23="alto",1,"falta riesgo"))) -> 0 | I22: I16_043-División de Planificación y Presupuesto | J22: Bajo
C23: H: Acompañamiento EE con subvención | D23: =IF(J21="bajo",0,IF(J21="medio",0.5,IF(J21="alto",1,"falta riesgo"))) -> 0 | I23: I20_011-División de Planificación y Presupuesto | J23: Bajo
C24: H: Sesión de tutoria de cupos | D24: =IF(J20="bajo",0,IF(J20="medio",0.5,IF(J20="alto",1,"falta riesgo"))) -> 0 | I24: I20_012-División de Planificación y Presupuesto | J24: Bajo
I25: I25_012-División de Planificación y Presupuesto | J25: Bajo
A26: DIPLAP | C26: CDC: Tickets de atención resueltos | D26: =IF(J27="bajo",0,IF(J27="medio",0.5,IF(J27="alto",1,"falta riesgo"))) -> 0 | I26: I21_002-División de Planificación y Presupuesto | J26: Bajo
C27: CDC: Sitios web con certificados de sitio seguro | D27: =IF(J26="bajo",0,IF(J26="medio",0.5,IF(J26="alto",1,"falta riesgo"))) -> 0 | I27: I16_054-División de Planificación y Presupuesto | J27: Bajo
C28: CDC: Sistemas definidos como críticos | D28: =IF(J25="bajo",0,IF(J25="medio",0.5,IF(J25="alto",1,"falta riesgo"))) -> 0 | I28: I19_012-División de Planificación y Presupuesto | J28: Bajo
C29: CDC: Asistencia vía SIGE | D29: =IF(J30="bajo",0,IF(J30="medio",0.5,IF(J30="alto",1,"falta riesgo"))) -> 0 | I29: I25_005-División de Planificación y Presupuesto | J29: Bajo
C30: CDC: Transacciones a través del sistema SIGPA | D30: =IF(J31="bajo",0,IF(J31="medio",0.5,IF(J31="alto",1,"falta riesgo"))) -> 0 | I30: I21_007-DAG | J30: Bajo
C31: CDC: Procesos documentados URAE | D31: =IF(J32="bajo",0,IF(J32="medio",0.5,IF(J32="alto",1,"falta riesgo"))) -> 0 | I31: I25_004-DAG | J31: Bajo
C32: PMG: Concentración del Gasto | D32: =IF(J28="bajo",0,IF(J28="medio",0.5,IF(J28="alto",1,"falta riesgo"))) -> 0 | I32: I23_019-DAG | J32: Bajo
C33: PMG: Transformación Digital | D33: =IF(J29="bajo",0,IF(J29="medio",0.5,IF(J29="alto",1,"falta riesgo"))) -> 0 | I33: I25_013-DAG | J33: Bajo
I34: I20_006-DAG | J34: Bajo
A35: DAG | C35: CDC: Solicitudes de beneficios y/o préstamos | D35: =IF(J33="bajo",0,IF(J33="medio",0.5,IF(J33="alto",1,"falta riesgo"))) -> 0 | I35: I20_005-DAG | J35: Bajo
C36: CDC: Expedientes de compras | D36: =IF(J34="bajo",0,IF(J34="medio",0.5,IF(J34="alto",1,"falta riesgo"))) -> 0 | I36: I19_020-UCE | J36: Bajo
C37: CDC: Cierres contables oportunos | D37: =IF(J36="bajo",0,IF(J36="medio",0.5,IF(J36="alto",1,"falta riesgo"))) -> 0 | I37: I21_011-UCE | J37: Bajo
C38: CDC: Contratos nuevos a honorarios NC | D38: =IF(J37="bajo",0,IF(J37="medio",0.5,IF(J37="alto",1,"falta riesgo"))) -> 0 | I38: I21_012-UCE | J38: Bajo
C39: PMG: Sistema Estado Verde | D39: =IF(J35="bajo",0,IF(J35="medio",0.5,IF(J35="alto",1,"falta riesgo"))) -> 0 | I39: I22_006-UCE | J39: Bajo
I40: I19_019-UCE | J40: Bajo
...

Sheet data_status_reg
B3: Cod_Sigemet | C3: Variable | D3: Regiones | E3: Estado
B4: I23_014 | C4: I23_014-SECREDUC 01 | D4: Tarapacá | E4: Bajo
B5: I23_014 | C5: I23_014-SECREDUC 02 | D5: Antofagasta | E5: Bajo
B6: I23_014 | C6: I23_014-SECREDUC 03 | D6: Atacama | E6: Bajo
B7: I23_014 | C7: I23_014-SECREDUC 04 | D7: Coquimbo | E7: Bajo
B8: I23_014 | C8: I23_014-SECREDUC 05 | D8: Valparaíso | E8: Bajo
B9: I23_014 | C9: I23_014-SECREDUC 06 | D9: O'Higgins | E9: Bajo
B10: I23_014 | C10: I23_014-SECREDUC 07 | D10: Maule | E10: Bajo
B11: I23_014 | C11: I23_014-SECREDUC 08 | D11: Biobío | E11: Bajo
B12: I23_014 | C12: I23_014-SECREDUC 09 | D12: La Araucanía | E12: Bajo
B13: I23_014 | C13: I23_014-SECREDUC 10 | D13: Los Lagos | E13: Bajo
B14: I23_014 | C14: I23_014-SECREDUC 11 | D14: Aysén | E14: Bajo
... B83: I25_006 | C83: I25_006-SECREDUC 16 | D83: Ñuble | E83: Bajo

Sheet Ev Proveedores
B3: EVALUACIÓN PROVEEDORES INDICADORES
B4: La evaluación de proveedores consiste en medir de manera mensual la calidad de la información que reportan las distintas Divisiones, Departamentos y Unidades Estratégicas que tienen indicadores PMG H y/o CDC. En esta medición se analizan principalmente tres variables: oportunidad, consistencia y completitud de la información , elementos fundamentales para el cumplimiento de los indicadores del Servicio.
D9: Cumpl. promedio | J9: Cumpl. promedio
C10: División | E10: Oportunidad | F10: Consistencia | G10: Completitud | I10: División | K10: Oportunidad | L10: Consistencia | M10: Completitud
C11: CPEIP | D11: 1 | E11: 1 | F11: 1 | G11: 1 | I11: Tarapacá | J11: 1 | K11: 1 | L11: 1 | M11: 1
C12: DAG | D12: 1 | E12: 1 | F12: 1 | G12: 1 | I12: Antofagasta | J12: 0.93 | K12: 1 | L12: 1 | M12: 0.8
C13: DEG | D13: 1 | E13: 1 | F13: 1 | G13: 1 | I13: Atacama | J13: 0.93 | K13: 1 | L13: 1 | M13: 0.8
C14: DIPLAP | D14: 0.86 | E14: 0.86 | F14: 0.86 | G14: 0.86 | I14: Coquimbo | J14: 1 | K14: 1 | L14: 1 | M14: 1
C15: CNT | D15: 1 | E15: 1 | F15: 1 | G15: 1 | I15: Valparaíso | J15: 0.93 | K15: 1 | L15: 0.8 | M15: 1
C16: Recursos Financieros | D16: 1 | E16: 1 | F16: 1 | G16: 1 | I16: O'Higgins | J16: 0.73 | K16: 1 | L16: 0.6 | M16: 0.6
C17: Subvenciones | D17: 1 | E17: 1 | F17: 1 | G17: 1 | I17: Maule | J17: 0.73 | K17: 1 | L17: 0.6 | M17: 0.6
C18: URAE | D18: 0 | E18: 0 | F18: 0 | G18: 0 | I18: Biobío | J18: 1 | K18: 1 | L18: 1 | M18: 1
C19: JURID | D19: 1 | E19: 1 | F19: 1 | G19: 1 | I19: La Araucanía | J19: 1 | K19: 1 | L19: 1 | M19: 1
C20: GABMIN | D20: 1 | E20: 1 | F20: 1 | G20: 1 | I20: Los Lagos | J20: 0.86 | K20: 1 | L20: 0.8 | M20: 0.8
C21: Auditoria | D21: 1 | E21: 1 | F21: 1 | G21: 1 | I21: Aysén | J21: 1 | K21: 1 | L21: 1 | M21: 1
C22: Estudios | D22: 1 | E22: 1 | F22: 1 | G22: 1 | I22: Magallanes | J22: 1 | K22: 1 | L22: 1 | M22: 1
... C26: Innovación | D26: 1 | E26: 1 | F26: 1 | G26: 1 | I26: Ñuble | J26: 0.83 | K26: 1 | L26: 0.5 | M26: 1
C27: TP | D27: 0.33 | E27: 0 | F27: 1 | G27: 0
C28: UCE | D28: 1 | E28: 1 | F28: 1 | G28: 1
C30: LEYENDA EVALUACIÓN PROVEEDORES
C31: Oportunidad | E31: Se entrega la información de variables e indicadores dentro del plazo establecido
C32: Consistencia | E32: La información entregada es consistente para cada variable e indicador (avance, medios, análisis y riesgo)
C33: Completitud | E33: Se carga toda la información de cada variable e indicador (avance, medios, análisis y riesgo)

Sheet Convenios ADP
B2: Convenios Alta Dirección Pública | I2: Acum ABRIL - 2025
B3: Hitos ADP ocurridos al 13 de ABRIL
B4: El cumplimiento de los hitos está normado por la ley 19.882 e instructivo del Servicio Civil (SC)
B5: Servicio | C5: Convenio totalmente tramitado | E5: Monitoreo Año 1 | F5: Evaluación Año 1 | G5: Monitoreo Año 2 | H5: Evaluacion Año 2 | I5: Monitoreo Año 3 | J5: Evaluación Año 3
B6: CRUCH | C6: 44725 | E6: 44908 | F6: 45090 | G6: 45273 | H6: 45456 | I6: 45639 | J6: 45821
B7: JUNAEB | C7: 44789 | E7: 44608 | F7: 45154 | G7: 45338 | H7: 45520 | I7: 45704 | J7: 45885
B8: Agencia de Calidad | C8: 44868 | E8: 45049 | F8: 45233 | G8: 45415 | H8: 45599 | I8: 45780 | J8: 45964
B9: DEP | C9: 45439 | E9: 45623 | F9: 45804 | G9: 45988 | H9: 46169 | I9: 46353 | J9: 46534
B10: Superintendencia de Educación | C10: 44900 | E10: 45082 | F10: 45265 | G10: 45448 | H10: 45631 | I10: 45813 | J10: 45813
B11: JUNJI | C11: 44930 | E11: 45111 | F11: 45295 | G11: 45477 | H11: 45661 | I11: 45842 | J11: 46026
B12: Superintendencia de Educación Superior | C12: 44958 | E12: 45139 | F12: 45323 | G12: 45505 | H12: 45689 | I12: 45870 | J12: 46054
B14: Leyenda | D14: Comentarios por Servicio:
B16: - Representa los Hitos acumulados que han sido ejecutados al año 2025. ​ | D16: CRUCH | E16: En enero 2025 se envió mediante mail del Jefe del Gabinete del Ministro, el resultado del monitoreo del tercer año de gestión.
B17: - Todos los Convenios de Alta Dirección Pública (CADP) expuestos, se encuentran vigentes a la fecha del reporte.​ | D17: JUNAEB | E17: En marzo 2025 se envió mediante mail del Jefe del Gabinete del Ministro, el resultado del monitoreo del tercer año de gestión.
B18: - Las fechas expuestas representan Las fechas de corte donde se inicia cada proceso.​ | D18: Agencia de Calidad | E18: En enero 2025 se tramitó totalmente el acto administrativo que aprueba el grado de cumplimiento global de las metas del convenio del 2do año de gestión.
D19: DEP | E19: En marzo 2025 se inició el monitoreo del primer año de gestión.
D20: Superintendencia de Educación | E20: En febrero 2025 se tramitó totalmente el acto administrativo que aprueba el grado de cumplimiento global de las metas del convenio del 2do año de gestión.
D21: JUNJI | E21: En febrero 2025 se tramitó totalmente el acto administrativo que aprueba el grado de cumplimiento global de las metas del convenio del 2do año de gestión.
D22: Superintendencia de Educación Superior | E22: En marzo 2025 se enviaron los antecedentes a la División Jurídica para la elaboración del acto administrativo de la evaluación del segundo año de gestión.

Sheet Gestión de riesgos
B1: SUBSECRETARÍA DE EDUCACIÓN
B3: Proceso de Gestión de Riesgos(PGR)
A4: _x000D_ | B4: ABRIL - 2025
B6: Herramientas del Proceso de Gestión de Riesgo | H6: Procesos | N6: Subprocesos | S6: Etapas | X6: Riesgos
B7: Instrumentos | C7: Estado | D7: Año última actualización | E7: Alerta | H7: =I23 -> 68 | N7: =L23 -> 187 | S7: =O23 -> 473 | X7: =R23 -> 526
B8: Política de Gestión de Riesgos | C8: Pendiente actualizar | D8: 2019
B9: Ranking de Procesos | C9: Actualizado | D9: 2024
B10: Matriz de Riesgos | C10: Actualizado | D10: 2024 | G10: Matriz de Riesgos 2024 – Subsecretaría de Educación
B11: Ranking de Riesgos | C11: Actualizado | D11: 2024 | G11: Nombre del CR | I11: Cantidad de Procesos | L11: Cantidad de Subprocesos | O11: Cantidad de Etapas | R11: Riesgos
B12: Señales de Alerta - Asociadas a MR | C12: Actualizado | D12: 2024 | R12: Cantidad de Riesgos | T12: Riesgos Financieros | V12: Riesgos Estratégicos | X12: Señales de Alerta
B13: Señales de Alerta - No Asociadas a MR | C13: Actualizado | D13: 2024
B14: Plan de Tratamiento de Riesgos | C14: Actualizado | D14: 2024 | G14: CPEIP | I14: 4 | L14: 8 | O14: 30 | R14: 53 | T14: 0 | V14: 8 | X14: 2
B15: Plan de Comunicaciones y Consulta | C15: Actualizado | D15: 2024 | G15: DAG | I15: 11 | L15: 30 | O15: 105 | R15: 105 | T15: 8 | V15: 0 | X15: 4
G16: DEG | I16: 19 | L16: 58 | O16: 99 | R16: 107 | T16: 8 | V16: 6 | X16: 7
B17: Monitoreo Plan de Tratamiento de Riesgos 2024 | G17: DIPLAP | I17: 15 | L17: 49 | O17: 127 | R17: 134 | T17: 12 | V17: 5 | X17: 7
B18: Tipo de Riesgos | C18: Cantidad de Riesgos | D18: Estado | E18: Alerta | G18: Ciberseguridad | I18: 1 | L18: 2 | O18: 4 | R18: 4 | T18: 0 | V18: 2 | X18: 2
B19: Financieros | C19: 16 | D19: Se realizará monitoreo con corte al 31/03 | G19: GabMin Estudios | I19: 5 | L19: 8 | O19: 22 | R19: 22 | T19: 0 | V19: 2 | X19: 0
B20: Estratégicos | C20: 13 | D20: Se realizará monitoreo con corte al 31/03 | G20: Jurídica | I20: 9 | L20: 22 | O20: 32 | R20: 33 | T20: 0 | V20: 0 | X20: 0
B21: Institucionales | C21: 35 | D21: Se realizará monitoreo con corte al 31/03 | G21: UCE | I21: 3 | L21: 8 | O21: 50 | R21: 62 | T21: 0 | V21: 10 | X21: 11
B22: Señales de Alerta | C22: 21 | D22: Se realizará monitoreo con corte al 31/03 | G22: Ayuda MINEDUC | I22: 1 | L22: 2 | O22: 4 | R22: 6 | T22: 0 | V22: 0 | X22: 3
B23: Señales de Alerta no asociadas a MR | C23: 2 | D23: Se realizará monitoreo con corte al 31/03 | G23: Total | I23: =SUM(I14:K22) -> 68 | L23: =SUM(L14:N22) -> 187 | O23: =SUM(O14:Q22) -> 473 | R23: =SUM(R14:S22) -> 526 | T23: =SUM(T14:U22) -> 28 | V23: =SUM(V14:W22) -> 33 | X23: =SUM(X14:Y22) -> 36
H26: Planes de Tratamiento | L26: Riesgos por CR que deben comprometer Planes de Tratamiento para el año 2024
H27: =Y38 -> 64 | L27: Nombre del CR | O27: RE | Q27: RE/SA | S27: RF | T27: RF/SA | V27: RI | W27: RI/SA | Y27: Total
L29: CPEIP | O29: 3 | Q29: 1 | S29: 0 | T29: 0 | V29: 3 | W29: 0 | Y29: 6
L30: DAG | O30: 0 | Q30: 0 | S30: 9 | T30: 3 | V30: 2 | W30: 1 | Y30: 11
H31: Estratégicos | L31: DEG | O31: 1 | Q31: 0 | S31: 3 | T31: 4 | V31: 2 | W31: 0 | Y31: 6
L32: DIPLAP | O32: 2 | Q32: 0 | S32: 4 | T32: 2 | V32: 9 | W32: 2 | Y32: 15
H33: =O38 -> 13 | L33: Ciberseguridad | O33: 2 | Q33: 2 | S33: 0 | T33: 0 | V33: 1 | W33: 1 | Y33: 3
L34: GabMin Estudios | O34: 1 | Q34: 0 | S34: 0 | T34: 0 | V34: 4 | W34: 0 | Y34: 5
L35: Jurídica | O35: 0 | Q35: 0 | S35: 0 | T35: 0 | V35: 5 | W35: 0 | Y35: 5
L36: UCE | O36: 4 | Q36: 1 | S36: 0 | T36: 0 | V36: 6 | W36: 1 | Y36: 10
H37: Financieros | L37: Ayuda MINEDUC | O37: 0 | Q37: 0 | S37: 0 | T37: 0 | V37: 3 | W37: 3 | Y37: 3
L38: Total | O38: =SUM(O29:P37) -> 13 | Q38: =SUM(Q29:R37) -> 4 | S38: =SUM(S29:S37) -> 16 | T38: =SUM(T29:U37) -> 9 | V38: =SUM(V29:V37) -> 35 | W38: =SUM(W29:X37) -> 8 | Y38: =SUM(Y29:Y37) -> 64
H39: =S38 -> 16
R42: Abreviaturas
H43: Institucionales | N43: Señales de Alerta | R43: RE: Riesgos Estratégicos | T43: RE/SA: Riesgos Estratégicos con Señal de Alerta
H45: =SUM(V38) -> 35 | O45: =SUM(Q38,T38,W38) -> 21 | R45: RF: Riesgos Financieros | T45: RF/SA: Riesgos Financieros con señal de Alerta
R47: RI: Riesgos Institucionales | T47: RI/SA: Riesgos Institucionales con Señal de Alerta

Sheet data_riesgos
B2: Matriz de Riesgo - Mapa de Calor
B3: Impacto
B4: Insignificantes | C4: Menores | D4: Moderadas | E4: Mayores | F4: Catastróficas
B5: 1 | C5: 2 | D5: 3 | E5: 4 | F5: 5
A6: 5 | B6: 0 | C6: 0 | D6: 2 | E6: 0 | F6: 0
A7: 4 | B7: 2 | C7: 12 | D7: 22 | E7: 19 | F7: 0
A8: 3 | B8: 3 | C8: 32 | D8: 86 | E8: 48 | F8: 2
A9: 2 | B9: 12 | C9: 58 | D9: 70 | E9: 31 | F9: 11
A10: 1 | B10: 35 | C10: 19 | D10: 25 | E10: 21 | F10: 16
C14: Probabilidad | D14: Impacto | E14: Total
C15: 1 | D15: 1 | E15: 29
C16: 2 | D16: 1 | E16: 11
C17: 3 | D17: 1 | E17: 3
C18: 4 | D18: 1 | E18: 1
C19: 5 | D19: 1 | E19: 0
C20: 1 | D20: 2 | E20: 22
C21: 2 | D21: 2 | E21: 55
C22: 3 | D22: 2 | E22: 33
C23: 4 | D23: 2 | E23: 14
C24: 5 | D24: 2 | E24: 0
C25: 1 | D25: 3 | E25: 25
C26: 2 | D26: 3 | E26: 72 | G26: Probabilidad | H26: 5
C27: 3 | D27: 3 | E27: 96
C28: 4 | D28: 3 | E28: 21
C29: 5 | D29: 3 | E29: 2
C30: 1 | D30: 4 | E30: 22
C31: 2 | D31: 4 | E31: 31 | H31: 4
C32: 3 | D32: 4 | E32: 45
C33: 4 | D33: 4 | E33: 18
C34: 5 | D34: 4 | E34: 0
C35: 1 | D35: 5 | E35: 14
C36: 2 | D36: 5 | E36: 10 | H36: 3
C37: 3 | D37: 5 | E37: 2
C38: 4 | D38: 5 | E38: 0
C39: 5 | D39: 5 | E39: 0
H41: 2
H46: 1
K70: IMPACTO

Sheet programas sociales
B1: PROGRAMAS SOCIALES
B2: MINISTERIO DE EDUCACIÓN | G2: ABRIL - 2025
K4: RESULTADO EX ANTE
K5: SUBSECRETARÍA / SERVICIO | M5: PROGRAMA | O5: CATEGORÍA
K6: Junta Nacional de Auxilio Escolar y Becas | M6: Beca de Apoyo a la Retención Escolar | O6: RF
K7: Junta Nacional de Auxilio Escolar y Becas | M7: Programa Habilidades para la Vida III | O7: RF
K8: Subsecretaría de Educación | M8: Educación Rural | O8: RF
K9: Subsecretaría de Educación | M9: Fortalecimiento del aprendizaje del inglés | O9: RF
K10: Subsecretaría de Educación | M10: Subvención Escolar Regular | O10: RF
E11: Monitoreo | K11: Subsecretaría de Educación Parvularia | M11: Jardines Infantiles y Sala Cuna modalidad No Convencional | O11: RF
E12: SUBSECRETARÍA / SERVICIO | H12: MONITOREO | K12: Subsecretaría de Educación Parvularia | M12: Vacaciones en mi Jardín | O12: BP
E13: Dirección de Educación Pública | H13: 2 | K13: Subsecretaría de Educación Superior | M13: Plan de Fortalecimiento de Universidades | O13: RF
E14: Junta Nacional de Auxilio Escolar y Becas | H14: 26 | K14: Subsecretaría de Educación Superior | M14: Beca Bicentenario | O14: RF
E15: Junta Nacional de Jardines Infantiles | H15: 5 | K15: Subsecretaría de Educación | M15: Red Maestro de Maestros | O15: RF
E16: Subsecretaria de Educación | H16: 29 | K16: Subsecretaría de Educación | M16: Subvención Pro-Retención | O16: RF
E17: Subsecretaría Educación Parvularia | H17: 6 | K17: Junta Nacional de Jardines Infantiles | M17: Programa Jardín Transitorio Estacional | O17: BP
E18: Subsecretaría Educación Superior | H18: 25 | K18: Junta Nacional de Jardines Infantiles | M18: Programa Alternativo de Atención al Párvulo | O18: BP
B20: SUBSECRETARÍA/SERVICIO | C20: NÚMERO DE PROGRAMAS 2024
B22: Dirección de Educación Pública | C22: 2 | F22: Monitoreo | H22: Total programas
B23: Junta Nacional de Auxilio Escolar y Becas | C23: 26 | F23: =SUM(H13:H18) -> 93 | H23: =SUM(C22:C27) -> 93
B24: Junta Nacional de Jardines Infantiles | C24: 5
B25: Subsecretaria de Educación | C25: 29 | K25: Leyenda:
B26: Subsecretaría Educación Parvularia | C26: 6 | F26: Fecha | H26: Total Ex - ante | K26: RF: Recomendación Favorable
B27: Subsecretaría Educación Superior | C27: 25 | F27: 45657 | H27: =COUNTA(O6:P27) -> 13 | K27: BP: Baja del Proceso

Sheet datos_graficos
A2: FECHA | B2: EVENTO | C2: POSICIÓN | D2: EJE
A3: 45646 | B3: Inicio Monitoreo 2024 ejecución año t-1 | C3: 2 | D3: 0
A4: 45294 | B4: Envío de orientaciones a contrapartes internas | C4: -1 | D4: 0
A5: 45317 | B5: Reporte en plataforma | C5: 1.5 | D5: 0
A6: 45677 | B6: Evaluación MDSyF | C6: -1 | D6: 0
A7: 45748 | B7: Publicación de informes de monitoreo | C7: 1 | D7: 0
A8: 45796 | B8: Inicio Ex ante | C8: 2 | D8: 0
A9: 45432 | B9: Envío de lineamientos internos | C9: 1 | D9: 0
A10: 45435 | B10: Iteración 1 | C10: -1 | D10: 0
A11: 45442 | B11: Iteración 2 | C11: -1 | D11: 0
A12: 45449 | B12: Iteración 3 | C12: -1 | D12: 0
A13: 45456 | B13: Iteración 4 | C13: -1 | D13: 0
A14: 45463 | B14: Cierre ex ante | C14: 1 | D14: 0
