Workbook

Sheet Portada
F11: Reporte mensual de avance de indicadores | G11: 2025
F12: ABRIL - 2025
F15: Departamento de Planificación y Control de Gestión
F16: División de Planificación y Presupuesto
F18: Subsecretaría de Educación

Sheet 01-PANEL
J2: SUBSECRETARÍA DE EDUCACIÓN
J4: ESTADO RIESGO INDICADORES
J5: POR INSTRUMENTO DE GESTIÓN | N5: ABRIL - 2025
C8: =_xlfn.CONCAT("PERIODO ", N5) -> PERIODO ABRIL - 2025 | G8: TIPO | K8: RIESGO BAJO | M8: RIESGO MEDIO | O8: RIESGO ALTO | R8: TOTAL INDICADORES
C10: TOTAL INDICADORES | G10: CDC NIVEL CENTRAL | K10: 34 | M10: 0 | O10: 0 | R10: =SUM($K10:$O10) -> 34
C11: PMG | D11: =R13 -> 6 | G11: CDC REGIONES | K11: 78 | M11: 0 | O11: 0 | R11: =SUM($K11:$O11) -> 78
C12: H | D12: =R12 -> 4 | G12: H | K12: 4 | M12: 0 | O12: 0 | R12: =SUM($K12:$O12) -> 4
C13: CDC NIVEL CENTRAL | D13: =R10 -> 34 | G13: PMG | K13: 6 | M13: 0 | O13: 0 | R13: =SUM($K13:$O13) -> 6
C14: CDC REGIONES | D14: =R11 -> 78 | G14: TOTAL | K14: =SUM(K10:K13) -> 122 | M14: =SUM(M10:M13) -> 0 | O14: =SUM(O10:O13) -> 0 | R14: =SUM(R10:R13) -> 122
C15: Total general | D15: =R14 -> 122
C24: INDICADORES CON RIESGO
C25: PMG | D25: =SUM(M13:O13) -> 0
C26: H | D26: =SUM(M12:O12) -> 0
C27: CDC NIVEL CENTRAL | D27: =SUM(M10:O10) -> 0
C28: CDC REGIONES | D28: =SUM(M11:O11) -> 0
C29: Total general | D29: =SUM(M14:O14) -> 0

Sheet data_panel
B3: PMG | C3: Bajo | D3: Medio | E3: Alto
B4: DAG | C4: 1 | D4: 0 | E4: 0
B5: DIPLAP | C5: 2 | D5: 0 | E5: 0
B6: Gab Subse | C6: 2 | D6: 0 | E6: 0
B7: H | C7: Bajo | D7: Medio | E7: Alto
B8: CPEIP | C8: 2 | D8: 0 | E8: 0
B9: DEG | C9: 2 | D9: 0 | E9: 0
B10: UCE | C10: 2 | D10: 0 | E10: 0
B11: CDC | C11: Bajo | D11: Medio | E11: Alto
B12: CPEIP | C12: 3 | D12: 0 | E12: 0
B13: DAG | C13: 4 | D13: 0 | E13: 0
B14: DEG | C14: 3 | D14: 0 | E14: 0
B15: Jurídica | C15: 7 | D15: 0 | E15: 0
B16: DIPLAP | C16: 6 | D16: 0 | E16: 0
B17: Gab Ministro | C17: 3 | D17: 0 | E17: 0
B18: Gab Subse | C18: 3 | D18: 0 | E18: 0
B19: UCE | C19: 5 | D19: 0 | E19: 0
B23: CDC | C23: Bajo | D23: Medio | E23: Alto
B24: Antofagasta | C24: 5 | D24: 0 | E24: 0
B25: Arica y Parinacota | C25: 5 | D25: 0 | E25: 0
B26: Atacama | C26: 5 | D26: 0 | E26: 0
B27: Aysén | C27: 5 | D27: 0 | E27: 0
B28: Biobío | C28: 5 | D28: 0 | E28: 0
B29: Coquimbo | C29: 5 | D29: 0 | E29: 0
B30: La Araucanía | C30: 5 | D30: 0 | E30: 0
B31: Los Lagos | C31: 5 | D31: 0 | E31: 0
B32: Los Ríos | C32: 5 | D32: 0 | E32: 0
B33: Magallanes | C33: 5 | D33: 0 | E33: 0
B34: Maule | C34: 5 | D34: 0 | E34: 0
B35: Metropolitana | C35: 4 | D35: 0 | E35: 0
... B39: Ñuble | C39: 4 | D39: 0 | E39: 0

Sheet 02-ESTADO NC
A2: NIVEL CENTRAL: ESTADO DE RIESGO INDICADORES POR CR AL CIERRE DE | T2: ABRIL - 2025

Sheet 03-  ESTADO REGIONES
A1: REGIONES : ESTADO RIESGO INDICADORES POR CR AL CIERRE:
A2: ABRIL - 2025
B5: REGIÓN | C5: CDC: Acciones del plan regional ejecutadas | F5: CDC: solicitudes de certificados de estudio no disponibles en línea | I5: CDC: Acciones del plan fortalecimineto de la matrícula implementadas | L5: CDC: capacitaciones a sostenedores | O5: CDC: Estudiantes OAP que postulan a través del SAE
B6: Tarapacá | D6: =IF(data_status_reg!$E4="bajo",0,IF(data_status_reg!$E4="medio",0.5,IF(data_status_reg!$E4="alto",1,"falta riesgo"))) -> 0 | G6: =IF(data_status_reg!$E20="bajo",0,IF(data_status_reg!$E20="medio",0.5,IF(data_status_reg!$E20="alto",1,"falta riesgo"))) -> 0 | J6: =IF(data_status_reg!$E36="bajo",0,IF(data_status_reg!$E36="medio",0.5,IF(data_status_reg!$E36="alto",1,"falta riesgo"))) -> 0 | M6: =IF(data_status_reg!$E52="bajo",0,IF(data_status_reg!$E52="medio",0.5,IF(data_status_reg!$E52="alto",1,"falta riesgo"))) -> 0 | P6: =IF(data_status_reg!$E68="bajo",0,IF(data_status_reg!$E68="medio",0.5,IF(data_status_reg!$E68="alto",1,"falta riesgo"))) -> 0
B7: Antofagasta | D7: =IF(data_status_reg!$E5="bajo",0,IF(data_status_reg!$E5="medio",0.5,IF(data_status_reg!$E5="alto",1,"falta riesgo"))) -> 0 | G7: =IF(data_status_reg!$E21="bajo",0,IF(data_status_reg!$E21="medio",0.5,IF(data_status_reg!$E21="alto",1,"falta riesgo"))) -> 0 | J7: =IF(data_status_reg!$E37="bajo",0,IF(data_status_reg!$E37="medio",0.5,IF(data_status_reg!$E37="alto",1,"falta riesgo"))) -> 0 | M7: =IF(data_status_reg!$E53="bajo",0,IF(data_status_reg!$E53="medio",0.5,IF(data_status_reg!$E53="alto",1,"falta riesgo"))) -> 0 | P7: =IF(data_status_reg!$E69="bajo",0,IF(data_status_reg!$E69="medio",0.5,IF(data_status_reg!$E69="alto",1,"falta riesgo"))) -> 0
B8: Atacama | D8: =IF(data_status_reg!$E6="bajo",0,IF(data_status_reg!$E6="medio",0.5,IF(data_status_reg!$E6="alto",1,"falta riesgo"))) -> 0 | G8: =IF(data_status_reg!$E22="bajo",0,IF(data_status_reg!$E22="medio",0.5,IF(data_status_reg!$E22="alto",1,"falta riesgo"))) -> 0 | J8: =IF(data_status_reg!$E38="bajo",0,IF(data_status_reg!$E38="medio",0.5,IF(data_status_reg!$E38="alto",1,"falta riesgo"))) -> 0 | M8: =IF(data_status_reg!$E54="bajo",0,IF(data_status_reg!$E54="medio",0.5,IF(data_status_reg!$E54="alto",1,"falta riesgo"))) -> 0 | P8: =IF(data_status_reg!$E70="bajo",0,IF(data_status_reg!$E70="medio",0.5,IF(data_status_reg!$E70="alto",1,"falta riesgo"))) -> 0
B9: Coquimbo | D9: =IF(data_status_reg!$E7="bajo",0,IF(data_status_reg!$E7="medio",0.5,IF(data_status_reg!$E7="alto",1,"falta riesgo"))) -> 0 | G9: =IF(data_status_reg!$E23="bajo",0,IF(data_status_reg!$E23="medio",0.5,IF(data_status_reg!$E23="alto",1,"falta riesgo"))) -> 0 | J9: =IF(data_status_reg!$E39="bajo",0,IF(data_status_reg!$E39="medio",0.5,IF(data_status_reg!$E39="alto",1,"falta riesgo"))) -> 0 | M9: =IF(data_status_reg!$E55="bajo",0,IF(data_status_reg!$E55="medio",0.5,IF(data_status_reg!$E55="alto",1,"falta riesgo"))) -> 0 | P9: =IF(data_status_reg!$E71="bajo",0,IF(data_status_reg!$E71="medio",0.5,IF(data_status_reg!$E71="alto",1,"falta riesgo"))) -> 0
B10: Valparaíso | D10: =IF(data_status_reg!$E8="bajo",0,IF(data_status_reg!$E8="medio",0.5,IF(data_status_reg!$E8="alto",1,"falta riesgo"))) -> 0 | G10: =IF(data_status_reg!$E24="bajo",0,IF(data_status_reg!$E24="medio",0.5,IF(data_status_reg!$E24="alto",1,"falta riesgo"))) -> 0 | J10: =IF(data_status_reg!$E40="bajo",0,IF(data_status_reg!$E40="medio",0.5,IF(data_status_reg!$E40="alto",1,"falta riesgo"))) -> 0 | M10: =IF(data_status_reg!$E56="bajo",0,IF(data_status_reg!$E56="medio",0.5,IF(data_status_reg!$E56="alto",1,"falta riesgo"))) -> 0 | P10: =IF(data_status_reg!$E72="bajo",0,IF(data_status_reg!$E72="medio",0.5,IF(data_status_reg!$E72="alto",1,"falta riesgo"))) -> 0
B11: O'Higgins | D11: =IF(data_status_reg!$E9="bajo",0,IF(data_status_reg!$E9="medio",0.5,IF(data_status_reg!$E9="alto",1,"falta riesgo"))) -> 0 | G11: =IF(data_status_reg!$E25="bajo",0,IF(data_status_reg!$E25="medio",0.5,IF(data_status_reg!$E25="alto",1,"falta riesgo"))) -> 0 | J11: =IF(data_status_reg!$E41="bajo",0,IF(data_status_reg!$E41="medio",0.5,IF(data_status_reg!$E41="alto",1,"falta riesgo"))) -> 0 | M11: =IF(data_status_reg!$E57="bajo",0,IF(data_status_reg!$E57="medio",0.5,IF(data_status_reg!$E57="alto",1,"falta riesgo"))) -> 0 | P11: =IF(data_status_reg!$E73="bajo",0,IF(data_status_reg!$E73="medio",0.5,IF(data_status_reg!$E73="alto",1,"falta riesgo"))) -> 0
B12: Maule | D12: =IF(data_status_reg!$E10="bajo",0,IF(data_status_reg!$E10="medio",0.5,IF(data_status_reg!$E10="alto",1,"falta riesgo"))) -> 0 | G12: =IF(data_status_reg!$E26="bajo",0,IF(data_status_reg!$E26="medio",0.5,IF(data_status_reg!$E26="alto",1,"falta riesgo"))) -> 0 | J12: =IF(data_status_reg!$E42="bajo",0,IF(data_status_reg!$E42="medio",0.5,IF(data_status_reg!$E42="alto",1,"falta riesgo"))) -> 0 | M12: =IF(data_status_reg!$E58="bajo",0,IF(data_status_reg!$E58="medio",0.5,IF(data_status_reg!$E58="alto",1,"falta riesgo"))) -> 0 | P12: =IF(data_status_reg!$E74="bajo",0,IF(data_status_reg!$E74="medio",0.5,IF(data_status_reg!$E74="alto",1,"falta riesgo"))) -> 0
B13: Biobío | D13: =IF(data_status_reg!$E11="bajo",0,IF(data_status_reg!$E11="medio",0.5,IF(data_status_reg!$E11="alto",1,"falta riesgo"))) -> 0 | G13: =IF(data_status_reg!$E27="bajo",0,IF(data_status_reg!$E27="medio",0.5,IF(data_status_reg!$E27="alto",1,"falta riesgo"))) -> 0 | J13: =IF(data_status_reg!$E43="bajo",0,IF(data_status_reg!$E43="medio",0.5,IF(data_status_reg!$E43="alto",1,"falta riesgo"))) -> 0 | M13: =IF(data_status_reg!$E59="bajo",0,IF(data_status_reg!$E59="medio",0.5,IF(data_status_reg!$E59="alto",1,"falta riesgo"))) -> 0 | P13: =IF(data_status_reg!$E75="bajo",0,IF(data_status_reg!$E75="medio",0.5,IF(data_status_reg!$E75="alto",1,"falta riesgo"))) -> 0
B14: Araucanía | D14: =IF(data_status_reg!$E12="bajo",0,IF(data_status_reg!$E12="medio",0.5,IF(data_status_reg!$E12="alto",1,"falta riesgo"))) -> 0 | G14: =IF(data_status_reg!$E28="bajo",0,IF(data_status_reg!$E28="medio",0.5,IF(data_status_reg!$E28="alto",1,"falta riesgo"))) -> 0 | J14: =IF(data_status_reg!$E44="bajo",0,IF(data_status_reg!$E44="medio",0.5,IF(data_status_reg!$E44="alto",1,"falta riesgo"))) -> 0 | M14: =IF(data_status_reg!$E60="bajo",0,IF(data_status_reg!$E60="medio",0.5,IF(data_status_reg!$E60="alto",1,"falta riesgo"))) -> 0 | P14: =IF(data_status_reg!$E76="bajo",0,IF(data_status_reg!$E76="medio",0.5,IF(data_status_reg!$E76="alto",1,"falta riesgo"))) -> 0
B15: Los Lagos | D15: =IF(data_status_reg!$E13="bajo",0,IF(data_status_reg!$E13="medio",0.5,IF(data_status_reg!$E13="alto",1,"falta riesgo"))) -> 0 | G15: =IF(data_status_reg!$E29="bajo",0,IF(data_status_reg!$E29="medio",0.5,IF(data_status_reg!$E29="alto",1,"falta riesgo"))) -> 0 | J15: =IF(data_status_reg!$E45="bajo",0,IF(data_status_reg!$E45="medio",0.5,IF(data_status_reg!$E45="alto",1,"falta riesgo"))) -> 0 | M15: =IF(data_status_reg!$E61="bajo",0,IF(data_status_reg!$E61="medio",0.5,IF(data_status_reg!$E61="alto",1,"falta riesgo"))) -> 0 | P15: =IF(data_status_reg!$E77="bajo",0,IF(data_status_reg!$E77="medio",0.5,IF(data_status_reg!$E77="alto",1,"falta riesgo"))) -> 0
B16: Aysén | D16: =IF(data_status_reg!$E14="bajo",0,IF(data_status_reg!$E14="medio",0.5,IF(data_status_reg!$E14="alto",1,"falta riesgo"))) -> 0 | G16: =IF(data_status_reg!$E30="bajo",0,IF(data_status_reg!$E30="medio",0.5,IF(data_status_reg!$E30="alto",1,"falta riesgo"))) -> 0 | J16: =IF(data_status_reg!$E46="bajo",0,IF(data_status_reg!$E46="medio",0.5,IF(data_status_reg!$E46="alto",1,"falta riesgo"))) -> 0 | M16: =IF(data_status_reg!$E62="bajo",0,IF(data_status_reg!$E62="medio",0.5,IF(data_status_reg!$E62="alto",1,"falta riesgo"))) -> 0 | P16: =IF(data_status_reg!$E78="bajo",0,IF(data_status_reg!$E78="medio",0.5,IF(data_status_reg!$E78="alto",1,"falta riesgo"))) -> 0
B17: Magallanes | D17: =IF(data_status_reg!$E15="bajo",0,IF(data_status_reg!$E15="medio",0.5,IF(data_status_reg!$E15="alto",1,"falta riesgo"))) -> 0 | G17: =IF(data_status_reg!$E31="bajo",0,IF(data_status_reg!$E31="medio",0.5,IF(data_status_reg!$E31="alto",1,"falta riesgo"))) -> 0 | J17: =IF(data_status_reg!$E47="bajo",0,IF(data_status_reg!$E47="medio",0.5,IF(data_status_reg!$E47="alto",1,"falta riesgo"))) -> 0 | M17: =IF(data_status_reg!$E63="bajo",0,IF(data_status_reg!$E63="medio",0.5,IF(data_status_reg!$E63="alto",1,"falta riesgo"))) -> 0 | P17: =IF(data_status_reg!$E79="bajo",0,IF(data_status_reg!$E79="medio",0.5,IF(data_status_reg!$E79="alto",1,"falta riesgo"))) -> 0
B18: Metropolitana | D18: =IF(data_status_reg!$E16="bajo",0,IF(data_status_reg!$E16="medio",0.5,IF(data_status_reg!$E16="alto",1,"falta riesgo"))) -> 0 | G18: No aplica | J18: =IF(data_status_reg!$E48="bajo",0,IF(data_status_reg!$E48="medio",0.5,IF(data_status_reg!$E48="alto",1,"falta riesgo"))) -> 0 | M18: =IF(data_status_reg!$E64="bajo",0,IF(data_status_reg!$E64="medio",0.5,IF(data_status_reg!$E64="alto",1,"falta riesgo"))) -> 0 | P18: =IF(data_status_reg!$E80="bajo",0,IF(data_status_reg!$E80="medio",0.5,IF(data_status_reg!$E80="alto",1,"falta riesgo"))) -> 0
B19: Los Ríos | D19: =IF(data_status_reg!$E17="bajo",0,IF(data_status_reg!$E17="medio",0.5,IF(data_status_reg!$E17="alto",1,"falta riesgo"))) -> 0 | G19: =IF(data_status_reg!$E33="bajo",0,IF(data_status_reg!$E33="medio",0.5,IF(data_status_reg!$E33="alto",1,"falta riesgo"))) -> 0 | J19: =IF(data_status_reg!$E49="bajo",0,IF(data_status_reg!$E49="medio",0.5,IF(data_status_reg!$E49="alto",1,"falta riesgo"))) -> 0 | M19: =IF(data_status_reg!$E65="bajo",0,IF(data_status_reg!$E65="medio",0.5,IF(data_status_reg!$E65="alto",1,"falta riesgo"))) -> 0 | P19: =IF(data_status_reg!$E81="bajo",0,IF(data_status_reg!$E81="medio",0.5,IF(data_status_reg!$E81="alto",1,"falta riesgo"))) -> 0
B20: Arica y Parinacota | D20: =IF(data_status_reg!$E18="bajo",0,IF(data_status_reg!$E18="medio",0.5,IF(data_status_reg!$E18="alto",1,"falta riesgo"))) -> 0 | G20: =IF(data_status_reg!$E34="bajo",0,IF(data_status_reg!$E34="medio",0.5,IF(data_status_reg!$E34="alto",1,"falta riesgo"))) -> 0 | J20: =IF(data_status_reg!$E50="bajo",0,IF(data_status_reg!$E50="medio",0.5,IF(data_status_reg!$E50="alto",1,"falta riesgo"))) -> 0 | M20: =IF(data_status_reg!$E66="bajo",0,IF(data_status_reg!$E66="medio",0.5,IF(data_status_reg!$E66="alto",1,"falta riesgo"))) -> 0 | P20: =IF(data_status_reg!$E82="bajo",0,IF(data_status_reg!$E82="medio",0.5,IF(data_status_reg!$E82="alto",1,"falta riesgo"))) -> 0
B21: Ñuble | D21: =IF(data_status_reg!$E19="bajo",0,IF(data_status_reg!$E19="medio",0.5,IF(data_status_reg!$E19="alto",1,"falta riesgo"))) -> 0 | G21: No aplica | J21: =IF(data_status_reg!$E51="bajo",0,IF(data_status_reg!$E51="medio",0.5,IF(data_status_reg!$E51="alto",1,"falta riesgo"))) -> 0 | M21: =IF(data_status_reg!$E67="bajo",0,IF(data_status_reg!$E67="medio",0.5,IF(data_status_reg!$E67="alto",1,"falta riesgo"))) -> 0 | P21: =IF(data_status_reg!$E83="bajo",0,IF(data_status_reg!$E83="medio",0.5,IF(data_status_reg!$E83="alto",1,"falta riesgo"))) -> 0

Sheet data_status_NC
E1: Valor Informe Mes
A2: Gabinete Ministro
C3: CDC: Solicitudes de información respondidas | D3: =IF($E3="bajo",0,IF($E3="medio",0.5,IF($E3="alto",1,"falta riesgo"))) -> 0 | E3: bajo
C4: CDC: Documentos publicados en web Centro de Estudios | D4: =IF($E4="bajo",0,IF($E4="medio",0.5,IF($E4="alto",1,"falta riesgo"))) -> 0 | E4: bajo
C5: CDC: Auditorías del Plan Anual de Auditoría | D5: =IF($E5="bajo",0,IF($E5="medio",0.5,IF($E5="alto",1,"falta riesgo"))) -> 0 | E5: bajo
A7: Gabinete Subsecretaria | C7: CDC: Solicitudes de certificados de estudio | D7: =IF($E7="bajo",0,IF($E7="medio",0.5,IF($E7="alto",1,"falta riesgo"))) -> 0 | E7: bajo
C8: CDC: Acciones formativas del Centro de Innovación | D8: =IF($E8="bajo",0,IF($E8="medio",0.5,IF($E8="alto",1,"falta riesgo"))) -> 0 | E8: bajo
C9: CDC: Compra de equipamiento | D9: =IF($E9="bajo",0,IF($E9="medio",0.5,IF($E9="alto",1,"falta riesgo"))) -> 0 | E9: bajo
C10: PMG: Sistema Calidad de Servicio y Experiencia | D10: =IF($E10="bajo",0,IF($E10="medio",0.5,IF($E10="alto",1,"falta riesgo"))) -> 0 | E10: bajo
C11: PMG: Medidas de Equidad y Género | D11: =IF($E11="bajo",0,IF($E11="medio",0.5,IF($E11="alto",1,"falta riesgo"))) -> 0 | E11: bajo
A13: CPEIP | C13: CDC: Elaboración de informe formación docente | D13: =IF($E13="bajo",0,IF($E13="medio",0.5,IF($E13="alto",1,"falta riesgo"))) -> 0 | E13: bajo
C14: CDC: Formación de bienestar docente | D14: =IF($E14="bajo",0,IF($E14="medio",0.5,IF($E14="alto",1,"falta riesgo"))) -> 0 | E14: bajo
C15: CDC: Informe proyecto de ley carrera directiva | D15: =IF($E15="bajo",0,IF($E15="medio",0.5,IF($E15="alto",1,"falta riesgo"))) -> 0 | E15: bajo
C16: H: Provincias que participan de acciones de CPEIP | D16: =IF($E16="bajo",0,IF($E16="medio",0.5,IF($E16="alto",1,"falta riesgo"))) -> 0 | E16: bajo
A18: DEG | C18: CDC: Inscipción para completar los estudios | D18: =IF($E18="bajo",0,IF($E18="medio",0.5,IF($E18="alto",1,"falta riesgo"))) -> 0 | E18: bajo
C19: CDC: Acciones plan de difusión | D19: =IF($E19="bajo",0,IF($E19="medio",0.5,IF($E19="alto",1,"falta riesgo"))) -> 0 | E19: bajo
C20: CDC: Procesos de validación de estudios | D20: =IF($E20="bajo",0,IF($E20="medio",0.5,IF($E20="alto",1,"falta riesgo"))) -> 0 | E20: bajo
C21: H: Implementación del Programa "A convivir se Aprende" | D21: =IF($E21="bajo",0,IF($E21="medio",0.5,IF($E21="alto",1,"falta riesgo"))) -> 0 | E21: bajo
A23: DIPLAP | C23: CDC: Tickets de atención resueltos | D23: =IF($E23="bajo",0,IF($E23="medio",0.5,IF($E23="alto",1,"falta riesgo"))) -> 0 | E23: bajo
C24: CDC: Sitios web con certificados de sitio seguro | D24: =IF($E24="bajo",0,IF($E24="medio",0.5,IF($E24="alto",1,"falta riesgo"))) -> 0 | E24: bajo
C25: CDC: Sistemas definidos como críticos | D25: =IF($E25="bajo",0,IF($E25="medio",0.5,IF($E25="alto",1,"falta riesgo"))) -> 0 | E25: bajo
C26: CDC: Asistencia vía SIGE | D26: =IF($E26="bajo",0,IF($E26="medio",0.5,IF($E26="alto",1,"falta riesgo"))) -> 0 | E26: bajo
C27: CDC: Transacciones a través del sistema SIGPA | D27: =IF($E27="bajo",0,IF($E27="medio",0.5,IF($E27="alto",1,"falta riesgo"))) -> 0 | E27: bajo
C28: CDC: Procesos documentados URAE | D28: =IF($E28="bajo",0,IF($E28="medio",0.5,IF($E28="alto",1,"falta riesgo"))) -> 0 | E28: bajo
C29: PMG: Concentración del Gasto | D29: =IF($E29="bajo",0,IF($E29="medio",0.5,IF($E29="alto",1,"falta riesgo"))) -> 0 | E29: bajo
C30: PMG: Transformación Digital | D30: =IF($E30="bajo",0,IF($E30="medio",0.5,IF($E30="alto",1,"falta riesgo"))) -> 0 | E30: bajo
A32: DAG | C32: CDC: Solicitudes de beneficios y/o préstamos | D32: =IF($E32="bajo",0,IF($E32="medio",0.5,IF($E32="alto",1,"falta riesgo"))) -> 0 | E32: bajo
C33: CDC: Expedientes de compras | D33: =IF($E33="bajo",0,IF($E33="medio",0.5,IF($E33="alto",1,"falta riesgo"))) -> 0 | E33: bajo
C34: CDC: Cierres contables oportunos | D34: =IF($E34="bajo",0,IF($E34="medio",0.5,IF($E34="alto",1,"falta riesgo"))) -> 0 | E34: bajo
C35: CDC: Contratos nuevos a honorarios NC | D35: =IF($E35="bajo",0,IF($E35="medio",0.5,IF($E35="alto",1,"falta riesgo"))) -> 0 | E35: bajo
C36: PMG: Sistema Estado Verde | D36: =IF($E36="bajo",0,IF($E36="medio",0.5,IF($E36="alto",1,"falta riesgo"))) -> 0 | E36: bajo
C37: PMG: Sistema de Riesgos Psicosociales laborales | D37: =IF($E37="bajo",0,IF($E37="medio",0.5,IF($E37="alto",1,"falta riesgo"))) -> 0 | E37: bajo
A39: UCE | C39: CDC: Recursos de Lectura, Aprendizaje y Bibliotecas | D39: =IF($E39="bajo",0,IF($E39="medio",0.5,IF($E39="alto",1,"falta riesgo"))) -> 0 | E39: bajo
C40: CDC: Ejecución del plan de Desarrollo Curricular | D40: =IF($E40="bajo",0,IF($E40="medio",0.5,IF($E40="alto",1,"falta riesgo"))) -> 0 | E40: bajo
C41: CDC: Difusión de instrumentos curriculares | D41: =IF($E41="bajo",0,IF($E41="medio",0.5,IF($E41="alto",1,"falta riesgo"))) -> 0 | E41: bajo
C42: CDC: Modernización de textos escolares | D42: =IF($E42="bajo",0,IF($E42="medio",0.5,IF($E42="alto",1,"falta riesgo"))) -> 0 | E42: bajo
C43: CDC: Ejecución del plan de Evaluación y Estándares | D43: =IF($E43="bajo",0,IF($E43="medio",0.5,IF($E43="alto",1,"falta riesgo"))) -> 0 | E43: bajo
C44: H: Entrega de Kit evaluativo de los EE subvencionados | D44: =IF($E44="bajo",0,IF($E44="medio",0.5,IF($E44="alto",1,"falta riesgo"))) -> 0 | E44: bajo
C45: H: Textos Escolares entregados | D45: =IF($E45="bajo",0,IF($E45="medio",0.5,IF($E45="alto",1,"falta riesgo"))) -> 0 | E45: bajo
A47: Jurídica | C47: CDC: Recursos de apelación, reclamación | D47: =IF($E47="bajo",0,IF($E47="medio",0.5,IF($E47="alto",1,"falta riesgo"))) -> 0 | E47: bajo
...

Sheet data_status_reg
B3: Cod_Sigemet | C3: Variable | D3: Regiones | E3: Estado
B4: I23_014 | C4: I23_014-SECREDUC 01 | D4: Tarapacá | E4: Bajo
B5: I23_014 | C5: I23_014-SECREDUC 02 | D5: Antofagasta | E5: Bajo
B6: I23_014 | C6: I23_014-SECREDUC 03 | D6: Atacama | E6: Bajo
B7: I23_014 | C7: I23_014-SECREDUC 04 | D7: Coquimbo | E7: Bajo
B8: I23_014 | C8: I23_014-SECREDUC 05 | D8: Valparaíso | E8: Bajo
B9: I23_014 | C9: I23_014-SECREDUC 06 | D9: O'Higgins | E9: Bajo
B10: I23_014 | C10: I23_014-SECREDUC 07 | D10: Maule | E10: Bajo
B11: I23_014 | C11: I23_014-SECREDUC 08 | D11: Biobío | E11: Bajo
B12: I23_014 | C12: I23_014-SECREDUC 09 | D12: La Araucanía | E12: Bajo
B13: I23_014 | C13: I23_014-SECREDUC 10 | D13: Los Lagos | E13: Bajo
B14: I23_014 | C14: I23_014-SECREDUC 11 | D14: Aysén | E14: Bajo
... B83: I25_006 | C83: I25_006-SECREDUC 16 | D83: Ñuble | E83: Bajo

Sheet Ev Proveedores
B3: EVALUACIÓN PROVEEDORES INDICADORES
B4: La evaluación de proveedores consiste en medir de manera mensual la calidad de la información que reportan las distintas Divisiones, Departamentos y Unidades Estratégicas que tienen indicadores PMG H y/o CDC. En esta medición se analizan principalmente tres variables: oportunidad, consistencia y completitud de la información , elementos fundamentales para el cumplimiento de los indicadores del Servicio.
D9: Cumpl. promedio | J9: Cumpl. promedio
C10: División | E10: Oportunidad | F10: Consistencia | G10: Completitud | I10: División | K10: Oportunidad | L10: Consistencia | M10: Completitud
C30: LEYENDA EVALUACIÓN PROVEEDORES
C31: Oportunidad | E31: Se entrega la información de variables e indicadores dentro del plazo establecido
C32: Consistencia | E32: La información entregada es consistente para cada variable e indicador (avance, medios, análisis y riesgo)
C33: Completitud | E33: Se carga toda la información de cada variable e indicador (avance, medios, análisis y riesgo)

Sheet Convenios ADP
B2: Convenios Alta Dirección Pública I Nivel | I2: Acum ABRIL - 2025
B3: Hitos ADP ocurridos al 20 de ABRIL
B4: El cumplimiento de los hitos está normado por la ley 19.882 e instructivo del Servicio Civil (SC)
B5: Servicio | C5: Convenio totalmente tramitado | E5: Monitoreo Año 1 | F5: Evaluación Año 1 | G5: Monitoreo Año 2 | H5: Evaluacion Año 2 | I5: Monitoreo Año 3 | J5: Evaluación Año 3
B14: Leyenda | D14: Comentarios por Servicio:
B16: - Representa los Hitos acumulados que han sido ejecutados al año 2025. ​
B17: - Todos los Convenios de Alta Dirección Pública (CADP) expuestos, se encuentran vigentes a la fecha del reporte.​
B18: - Las fechas expuestas representan Las fechas de corte donde se inicia cada proceso.​

Sheet Convenios ADP_II
B2: Convenios Alta Dirección Pública II Nivel que está subrogando prolongadamente un I Nivel | I2: Acum ABRIL - 2025
B3: Hitos ADP ocurridos al 20 de ABRIL
B4: El cumplimiento de los hitos está normado por la ley 19.882 e instructivo del Servicio Civil (SC)
B5: Servicio | C5: Convenio totalmente tramitado | E5: Monitoreo Año 1 | F5: Evaluación Año 1 | G5: Monitoreo Año 2 | H5: Evaluacion Año 2 | I5: Monitoreo Año 3 | J5: Evaluación Año 3
B11: Leyenda | D11: Comentarios por Servicio:
B13: - Representa los Hitos acumulados que han sido ejecutados al año 2025. ​
B14: - Todos los Convenios de Alta Dirección Pública (CADP) expuestos, se encuentran vigentes a la fecha del reporte.​
B15: - Las fechas expuestas representan Las fechas de corte donde se inicia cada proceso.​

Sheet Gestión de riesgos
B1: SUBSECRETARÍA DE EDUCACIÓN
B3: Proceso de Gestión de Riesgos(PGR)
A4: _x000D_ | B4: ABRIL - 2025
B6: Herramientas del Proceso de Gestión de Riesgo | H6: Procesos | N6: Subprocesos | S6: Etapas | X6: Riesgos
B7: Instrumentos | C7: Estado | D7: Año última actualización | E7: Alerta | H7: =I23 -> 68 | N7: =L23 -> 187 | S7: =O23 -> 473 | X7: =R23 -> 526
B8: Política de Gestión de Riesgos | C8: Pendiente actualizar | D8: 2019
B9: Ranking de Procesos | C9: Actualizado | D9: 2024
B10: Matriz de Riesgos | C10: Actualizado | D10: 2024 | G10: Matriz de Riesgos 2024 – Subsecretaría de Educación
B11: Ranking de Riesgos | C11: Actualizado | D11: 2024 | G11: Nombre del CR | I11: Cantidad de Procesos | L11: Cantidad de Subprocesos | O11: Cantidad de Etapas | R11: Riesgos
B12: Señales de Alerta - Asociadas a MR | C12: Actualizado | D12: 2024 | R12: Cantidad de Riesgos | T12: Riesgos Financieros | V12: Riesgos Estratégicos | X12: Señales de Alerta
B13: Señales de Alerta - No Asociadas a MR | C13: Actualizado | D13: 2024
B14: Plan de Tratamiento de Riesgos | C14: Actualizado | D14: 2024 | G14: CPEIP | I14: 4 | L14: 8 | O14: 30 | R14: 53 | T14: 0 | V14: 8 | X14: 2
B15: Plan de Comunicaciones y Consulta | C15: Actualizado | D15: 2024 | G15: DAG | I15: 11 | L15: 30 | O15: 105 | R15: 105 | T15: 8 | V15: 0 | X15: 4
G16: DEG | I16: 19 | L16: 58 | O16: 99 | R16: 107 | T16: 8 | V16: 6 | X16: 7
B17: Monitoreo Plan de Tratamiento de Riesgos 2024 | G17: DIPLAP | I17: 15 | L17: 49 | O17: 127 | R17: 134 | T17: 12 | V17: 5 | X17: 7
B18: Tipo de Riesgos | C18: Cantidad de Riesgos | D18: Estado | E18: Alerta | G18: Ciberseguridad | I18: 1 | L18: 2 | O18: 4 | R18: 4 | T18: 0 | V18: 2 | X18: 2
B19: Financieros | C19: 16 | D19: Se hizo envío del 1° monitoreo al CAIGG, el 30/04 | G19: GabMin Estudios | I19: 5 | L19: 8 | O19: 22 | R19: 22 | T19: 0 | V19: 2 | X19: 0
B20: Estratégicos | C20: 13 | D20: Se hizo envío del 1° monitoreo al CAIGG, el 30/04 | G20: Jurídica | I20: 9 | L20: 22 | O20: 32 | R20: 33 | T20: 0 | V20: 0 | X20: 0
B21: Institucionales | C21: 35 | D21: Se hizo envío del 1° monitoreo al CAIGG, el 30/04 | G21: UCE | I21: 3 | L21: 8 | O21: 50 | R21: 62 | T21: 0 | V21: 10 | X21: 11
B22: Señales de Alerta | C22: 21 | D22: Se hizo envío del 1° monitoreo al CAIGG, el 30/04 | G22: Ayuda MINEDUC | I22: 1 | L22: 2 | O22: 4 | R22: 6 | T22: 0 | V22: 0 | X22: 3
B23: Señales de Alerta no asociadas a MR | C23: 2 | D23: Se hizo envío del 1° monitoreo al CAIGG, el 30/04 | G23: Total | I23: =SUM(I14:K22) -> 68 | L23: =SUM(L14:N22) -> 187 | O23: =SUM(O14:Q22) -> 473 | R23: =SUM(R14:S22) -> 526 | T23: =SUM(T14:U22) -> 28 | V23: =SUM(V14:W22) -> 33 | X23: =SUM(X14:Y22) -> 36
H26: Planes de Tratamiento | L26: Riesgos por CR que deben comprometer Planes de Tratamiento para el año 2024
H27: =Y38 -> 64 | L27: Nombre del CR | O27: RE | Q27: RE/SA | S27: RF | T27: RF/SA | V27: RI | W27: RI/SA | Y27: Total
L29: CPEIP | O29: 3 | Q29: 1 | S29: 0 | T29: 0 | V29: 3 | W29: 0 | Y29: 6
L30: DAG | O30: 0 | Q30: 0 | S30: 9 | T30: 3 | V30: 2 | W30: 1 | Y30: 11
H31: Estratégicos | L31: DEG | O31: 1 | Q31: 0 | S31: 3 | T31: 4 | V31: 2 | W31: 0 | Y31: 6
L32: DIPLAP | O32: 2 | Q32: 0 | S32: 4 | T32: 2 | V32: 9 | W32: 2 | Y32: 15
H33: =O38 -> 13 | L33: Ciberseguridad | O33: 2 | Q33: 2 | S33: 0 | T33: 0 | V33: 1 | W33: 1 | Y33: 3
L34: GabMin Estudios | O34: 1 | Q34: 0 | S34: 0 | T34: 0 | V34: 4 | W34: 0 | Y34: 5
L35: Jurídica | O35: 0 | Q35: 0 | S35: 0 | T35: 0 | V35: 5 | W35: 0 | Y35: 5
L36: UCE | O36: 4 | Q36: 1 | S36: 0 | T36: 0 | V36: 6 | W36: 1 | Y36: 10
H37: Financieros | L37: Ayuda MINEDUC | O37: 0 | Q37: 0 | S37: 0 | T37: 0 | V37: 3 | W37: 3 | Y37: 3
L38: Total | O38: =SUM(O29:P37) -> 13 | Q38: =SUM(Q29:R37) -> 4 | S38: =SUM(S29:S37) -> 16 | T38: =SUM(T29:U37) -> 9 | V38: =SUM(V29:V37) -> 35 | W38: =SUM(W29:X37) -> 8 | Y38: =SUM(Y29:Y37) -> 64
H39: =S38 -> 16
R42: Abreviaturas
H43: Institucionales | N43: Señales de Alerta | R43: RE: Riesgos Estratégicos | T43: RE/SA: Riesgos Estratégicos con Señal de Alerta
H45: =SUM(V38) -> 35 | O45: =SUM(Q38,T38,W38) -> 21 | R45: RF: Riesgos Financieros | T45: RF/SA: Riesgos Financieros con señal de Alerta
R47: RI: Riesgos Institucionales | T47: RI/SA: Riesgos Institucionales con Señal de Alerta

Sheet data_riesgos
B2: Matriz de Riesgo - Mapa de Calor
B3: Impacto
B4: Insignificantes | C4: Menores | D4: Moderadas | E4: Mayores | F4: Catastróficas
B5: 1 | C5: 2 | D5: 3 | E5: 4 | F5: 5
A6: 5 | B6: 0 | C6: 0 | D6: 2 | E6: 0 | F6: 0
A7: 4 | B7: 2 | C7: 12 | D7: 22 | E7: 19 | F7: 0
A8: 3 | B8: 3 | C8: 32 | D8: 86 | E8: 48 | F8: 2
A9: 2 | B9: 12 | C9: 58 | D9: 70 | E9: 31 | F9: 11
A10: 1 | B10: 35 | C10: 19 | D10: 25 | E10: 21 | F10: 16
C14: Probabilidad | D14: Impacto | E14: Total
C15: 1 | D15: 1 | E15: 29
C16: 2 | D16: 1 | E16: 11
C17: 3 | D17: 1 | E17: 3
C18: 4 | D18: 1 | E18: 1
C19: 5 | D19: 1 | E19: 0
C20: 1 | D20: 2 | E20: 22
C21: 2 | D21: 2 | E21: 55
C22: 3 | D22: 2 | E22: 33
C23: 4 | D23: 2 | E23: 14
C24: 5 | D24: 2 | E24: 0
C25: 1 | D25: 3 | E25: 25
C26: 2 | D26: 3 | E26: 72 | G26: Probabilidad | H26: 5
C27: 3 | D27: 3 | E27: 96
C28: 4 | D28: 3 | E28: 21
C29: 5 | D29: 3 | E29: 2
C30: 1 | D30: 4 | E30: 22
C31: 2 | D31: 4 | E31: 31 | H31: 4
C32: 3 | D32: 4 | E32: 45
C33: 4 | D33: 4 | E33: 18
C34: 5 | D34: 4 | E34: 0
C35: 1 | D35: 5 | E35: 14
C36: 2 | D36: 5 | E36: 10 | H36: 3
C37: 3 | D37: 5 | E37: 2
C38: 4 | D38: 5 | E38: 0
C39: 5 | D39: 5 | E39: 0
H41: 2
H46: 1
K70: IMPACTO

Sheet programas sociales
B1: PROGRAMAS SOCIALES
B2: MINISTERIO DE EDUCACIÓN | G2: ABRIL - 2025
B3: LÍNEA DE TIEMPO DE LOS PROCESOS DE EX ANTE Y MONITOREO DE LOS PROGRAMAS SOCIALES
K4: RESULTADO DEL PROCESO DE EVALUACIÓN EX ANTE 2025
K5: SUBSECRETARÍA / SERVICIO | M5: PROGRAMA SOCIAL | O5: CATEGORÍA
B10: Hitos del proceso | C10: Hitos de proceso de evaluación Ex Ante
E13: TOTAL DE PROGRAMAS SOCIALES MONITOREADOS 2024
B14: TOTAL PROGRAMAS SOCIALES MINEDUC 2025 | E14: SUBSECRETARÍA / SERVICIO | H14: MONITOREO
B15: SUBSECRETARÍA/SERVICIO | C15: NÚMERO DE PROGRAMAS SOCIALES
E21: TOTAL | H21: =SUM(H15:H20) -> 0
B22: TOTAL | C22: =SUM(C16:C21) -> 0 | E22: NOTA: El monitoreo se realiza a programas sociales implementados en 2024
K25: Leyenda:
K26: RF: Recomendación Favorable
K27: *: Programas se dieron de baja del proceso ex ante por parte del Servicio para reformularse en el proceso 2026
K28: EV: En evaluación por parte de Ministerio del desarrollo y Familia.

Sheet Planes de tratamientos
A1: SUBSECRETARÍA DE EDUCACIÓN
A3: Resultados Planes de Tratamiento
A4: Primer Trimestre -2025
B6: Planes de tratamiento | E6: Financieros | H6: Estratégicos | K6: Institucionales | N6: Señales de alerta
B7: =SUM(E13:E15) -> 64 | E7: =E13 -> 16 | H7: 10 | K7: =E15 -> 38 | N7: =F25 -> 20
A9: Tipo de Plan de Tratamiento | B9: Estado de cumplimiento | E9: Total
B11: Cumplidos | C11: Cumplidos Parcialmente | D11: No Cumplidos/ Con retraso.
A13: Financieros | B13: 2 | C13: 14 | D13: 0 | E13: =SUM(B13:D13) -> 16
A14: Estratégicos | B14: 0 | C14: 10 | D14: 0 | E14: =SUM(B14:D14) -> 10
A15: Institucionales | B15: 0 | C15: 38 | D15: 0 | E15: =SUM(B15:D15) -> 38
H17: Evaluación de Proveedores
I19: Cumpl.
A20: Cumplidos | B20: En proceso | C20: No cumplidos | H20: División | I20: Promedio | J20: Oportunidad | K20: Consistencia
A21: =SUM(B13:B15) -> 2 | B21: =SUM(C13:C15) -> 62 | C21: =SUM(D13:D15) -> 0
A23: Categoría | B23: Estado de implementación | F23: Total
B24: Implementación | D24: En proceso de implementación | E24: No implementada
A25: Señales de Alerta | B25: 4 | D25: 16 | E25: 4 | F25: =SUM(B25:D25) -> 20

Sheet Planes tratamientos
A1: SUBSECRETARÍA DE EDUCACIÓN
A3: Resultados Planes de Tratamiento
A4: Primer Trimestre - 2025
E6: Planes de tratamiento | J6: Financieros | Q6: Estratégicos | W6: Institucionales | AD6: Señales de Alerta
E8: 64 | K8: 16 | P8: 10 | V8: 38 | AD8: 20
Q11: Detalles de Cumplimiento -Planes de Tratamiento de Riesgos | AF11: 2025
B12: Tipo de Plan de Tratamiento | F12: Estado de cumplimiento | M12: Total | S12: 0 | T12: 1 | U12: 2 | V12: 3 | W12: 4 | X12: 5 | Y12: 6 | Z12: 7 | AA12: 8 | AB12: 9 | AC12: 10 | AD12: 11 | AE12: 12 | AF12: 13
S13: =IF(INT($J$18*14/64 - S$12) = 0,$J$18, INT($J$18*14/64 - S$12)) -> 5 | T13: =IF(INT($J$18*14/64 - T$12) = 0,$J$18, INT($J$18*14/64 - T$12)) -> 4 | U13: =IF(INT($J$18*14/64 - U$12) = 0,$J$18, INT($J$18*14/64 - U$12)) -> 3 | V13: =IF(INT($J$18*14/64 - V$12) = 0,$J$18, INT($J$18*14/64 - V$12)) -> 2 | W13: =IF(INT($J$18*14/64 - W$12) = 0,$J$18, INT($J$18*14/64 - W$12)) -> 1 | X13: =IF(INT($J$18*14/64 - X$12) = 0,$J$18, INT($J$18*14/64 - X$12)) -> 25 | Y13: =IF(INT($J$18*14/64 - Y$12) = 0,$J$18, INT($J$18*14/64 - Y$12)) -> -1 | Z13: =IF(INT($J$18*14/64 - Z$12) = 0,$J$18, INT($J$18*14/64 - Z$12)) -> -2 | ... AF13: =IF(INT($J$18*14/64 - AF$12) = 0,$J$18, INT($J$18*14/64 - AF$12)) -> -8
F14: Cumplidos | H14: Cumplidos Parcialmente | J14: No Cumplidos/ Con retraso. | R14: Institucionales | S14: =IF(INT($H$18*14/64 - S$12) = 0,$H$18, INT($H$18*14/64 - S$12)) -> 8 | T14: =IF(INT($H$18*14/64 - T$12) = 0,$H$18, INT($H$18*14/64 - T$12)) -> 7 | U14: =IF(INT($H$18*14/64 - U$12) = 0,$H$18, INT($H$18*14/64 - U$12)) -> 6 | V14: =IF(INT($H$18*14/64 - V$12) = 0,$H$18, INT($H$18*14/64 - V$12)) -> 5 | W14: =IF(INT($H$18*14/64 - W$12) = 0,$H$18, INT($H$18*14/64 - W$12)) -> 4 | X14: =IF(INT($H$18*14/64 - X$12) = 0,$H$18, INT($H$18*14/64 - X$12)) -> 3 | Y14: =IF(INT($H$18*14/64 - Y$12) = 0,$H$18, INT($H$18*14/64 - Y$12)) -> 2 | Z14: =IF(INT($H$18*14/64 - Z$12) = 0,$H$18, INT($H$18*14/64 - Z$12)) -> 1 | ... AF14: =IF(INT($H$18*14/64 - AF$12) = 0,$H$18, INT($H$18*14/64 - AF$12)) -> -5
S15: =IF(INT($F$18*14/64 - S$12) = 0,$F$18, INT($F$18*14/64 - S$12)) -> 2 | T15: =IF(INT($F$18*14/64 - T$12) = 0,$F$18, INT($F$18*14/64 - T$12)) -> 1 | U15: =IF(INT($F$18*14/64 - U$12) = 0,$F$18, INT($F$18*14/64 - U$12)) -> 10 | V15: =IF(INT($F$18*14/64 - V$12) = 0,$F$18, INT($F$18*14/64 - V$12)) -> -1 | W15: =IF(INT($F$18*14/64 - W$12) = 0,$F$18, INT($F$18*14/64 - W$12)) -> -2 | X15: =IF(INT($F$18*14/64 - X$12) = 0,$F$18, INT($F$18*14/64 - X$12)) -> -3 | Y15: =IF(INT($F$18*14/64 - Y$12) = 0,$F$18, INT($F$18*14/64 - Y$12)) -> -4 | Z15: =IF(INT($F$18*14/64 - Z$12) = 0,$F$18, INT($F$18*14/64 - Z$12)) -> -5 | ... AF15: =IF(INT($F$18*14/64 - AF$12) = 0,$F$18, INT($F$18*14/64 - AF$12)) -> -11
B16: Financieros | F16: 2 | H16: 14 | J16: 0 | M16: 16
B17: Estratégicos | F17: 0 | H17: 10 | J17: 0 | M17: 10 | S17: =IF(INT($J$17*14/64 - S$12) = 0,$J$17, INT($J$17*14/64 - S$12)) -> 0 | T17: =IF(INT($J$17*14/64 - T$12) = 0,$J$17, INT($J$17*14/64 - T$12)) -> -1 | U17: =IF(INT($J$17*14/64 - U$12) = 0,$J$17, INT($J$17*14/64 - U$12)) -> -2 | V17: =IF(INT($J$17*14/64 - V$12) = 0,$J$17, INT($J$17*14/64 - V$12)) -> -3 | W17: =IF(INT($J$17*14/64 - W$12) = 0,$J$17, INT($J$17*14/64 - W$12)) -> -4 | X17: =IF(INT($J$17*14/64 - X$12) = 0,$J$17, INT($J$17*14/64 - X$12)) -> -5 | Y17: =IF(INT($J$17*14/64 - Y$12) = 0,$J$17, INT($J$17*14/64 - Y$12)) -> -6 | Z17: =IF(INT($J$17*14/64 - Z$12) = 0,$J$17, INT($J$17*14/64 - Z$12)) -> -7 | ... AF17: =IF(INT($J$17*14/64 - AF$12) = 0,$J$17, INT($J$17*14/64 - AF$12)) -> -13
B18: Institucionales | F18: 10 | H18: 38 | J18: 25 | M18: 38 | R18: Estratégicos | S18: =IF(INT($H$17*14/64 - S$12) = 0,$H$17, INT($H$17*14/64 - S$12)) -> 2 | T18: =IF(INT($H$17*14/64 - T$12) = 0,$H$17, INT($H$17*14/64 - T$12)) -> 1 | U18: =IF(INT($H$17*14/64 - U$12) = 0,$H$17, INT($H$17*14/64 - U$12)) -> 10 | V18: =IF(INT($H$17*14/64 - V$12) = 0,$H$17, INT($H$17*14/64 - V$12)) -> -1 | W18: =IF(INT($H$17*14/64 - W$12) = 0,$H$17, INT($H$17*14/64 - W$12)) -> -2 | X18: =IF(INT($H$17*14/64 - X$12) = 0,$H$17, INT($H$17*14/64 - X$12)) -> -3 | Y18: =IF(INT($H$17*14/64 - Y$12) = 0,$H$17, INT($H$17*14/64 - Y$12)) -> -4 | Z18: =IF(INT($H$17*14/64 - Z$12) = 0,$H$17, INT($H$17*14/64 - Z$12)) -> -5 | ... AF18: =IF(INT($H$17*14/64 - AF$12) = 0,$H$17, INT($H$17*14/64 - AF$12)) -> -11
S19: =IF(INT($F$17*14/64 - S$12) = 0,$F$17, INT($F$17*14/64 - S$12)) -> 0 | T19: =IF(INT($F$17*14/64 - T$12) = 0,$F$17, INT($F$17*14/64 - T$12)) -> -1 | U19: =IF(INT($F$17*14/64 - U$12) = 0,$F$17, INT($F$17*14/64 - U$12)) -> -2 | V19: =IF(INT($F$17*14/64 - V$12) = 0,$F$17, INT($F$17*14/64 - V$12)) -> -3 | W19: =IF(INT($F$17*14/64 - W$12) = 0,$F$17, INT($F$17*14/64 - W$12)) -> -4 | X19: =IF(INT($F$17*14/64 - X$12) = 0,$F$17, INT($F$17*14/64 - X$12)) -> -5 | Y19: =IF(INT($F$17*14/64 - Y$12) = 0,$F$17, INT($F$17*14/64 - Y$12)) -> -6 | Z19: =IF(INT($F$17*14/64 - Z$12) = 0,$F$17, INT($F$17*14/64 - Z$12)) -> -7 | ... AF19: =IF(INT($F$17*14/64 - AF$12) = 0,$F$17, INT($F$17*14/64 - AF$12)) -> -13
S21: =IF(INT($J$16*14/64 - S$12) = 0,$J$16, INT($J$16*14/64 - S$12)) -> 0 | T21: =IF(INT($J$16*14/64 - T$12) = 0,$J$16, INT($J$16*14/64 - T$12)) -> -1 | U21: =IF(INT($J$16*14/64 - U$12) = 0,$J$16, INT($J$16*14/64 - U$12)) -> -2 | V21: =IF(INT($J$16*14/64 - V$12) = 0,$J$16, INT($J$16*14/64 - V$12)) -> -3 | W21: =IF(INT($J$16*14/64 - W$12) = 0,$J$16, INT($J$16*14/64 - W$12)) -> -4 | X21: =IF(INT($J$16*14/64 - X$12) = 0,$J$16, INT($J$16*14/64 - X$12)) -> -5 | Y21: =IF(INT($J$16*14/64 - Y$12) = 0,$J$16, INT($J$16*14/64 - Y$12)) -> -6 | Z21: =IF(INT($J$16*14/64 - Z$12) = 0,$J$16, INT($J$16*14/64 - Z$12)) -> -7 | ... AF21: =IF(INT($J$16*14/64 - AF$12) = 0,$J$16, INT($J$16*14/64 - AF$12)) -> -13
R22: Financieros | S22: =IF(INT($H$16*14/64 - S$12) = 0,$H$16, INT($H$16*14/64 - S$12)) -> 3 | T22: =IF(INT($H$16*14/64 - T$12) = 0,$H$16, INT($H$16*14/64 - T$12)) -> 2 | U22: =IF(INT($H$16*14/64 - U$12) = 0,$H$16, INT($H$16*14/64 - U$12)) -> 1 | V22: =IF(INT($H$16*14/64 - V$12) = 0,$H$16, INT($H$16*14/64 - V$12)) -> 14 | W22: =IF(INT($H$16*14/64 - W$12) = 0,$H$16, INT($H$16*14/64 - W$12)) -> -1 | X22: =IF(INT($H$16*14/64 - X$12) = 0,$H$16, INT($H$16*14/64 - X$12)) -> -2 | Y22: =IF(INT($H$16*14/64 - Y$12) = 0,$H$16, INT($H$16*14/64 - Y$12)) -> -3 | Z22: =IF(INT($H$16*14/64 - Z$12) = 0,$H$16, INT($H$16*14/64 - Z$12)) -> -4 | ... AF22: =IF(INT($H$16*14/64 - AF$12) = 0,$H$16, INT($H$16*14/64 - AF$12)) -> -10
S23: =IF(INT($F$16*14/64 - S$12) = 0,$F$16, INT($F$16*14/64 - S$12)) -> 2 | T23: =IF(INT($F$16*14/64 - T$12) = 0,$F$16, INT($F$16*14/64 - T$12)) -> -1 | U23: =IF(INT($F$16*14/64 - U$12) = 0,$F$16, INT($F$16*14/64 - U$12)) -> -2 | V23: =IF(INT($F$16*14/64 - V$12) = 0,$F$16, INT($F$16*14/64 - V$12)) -> -3 | W23: =IF(INT($F$16*14/64 - W$12) = 0,$F$16, INT($F$16*14/64 - W$12)) -> -4 | X23: =IF(INT($F$16*14/64 - X$12) = 0,$F$16, INT($F$16*14/64 - X$12)) -> -5 | Y23: =IF(INT($F$16*14/64 - Y$12) = 0,$F$16, INT($F$16*14/64 - Y$12)) -> -6 | Z23: =IF(INT($F$16*14/64 - Z$12) = 0,$F$16, INT($F$16*14/64 - Z$12)) -> -7 | ... AF23: =IF(INT($F$16*14/64 - AF$12) = 0,$F$16, INT($F$16*14/64 - AF$12)) -> -13
Q27: Evaluación de Proveedores
T29: Cumpl. Promedio
Q30: División | W30: Oportunidad | Z30: Consistencia | AC30: Completitud
B33: Categoría | F33: Estado de implementación | M33: Total
F34: Implementación | I34: En proceso de implementación | K34: No implementada
B35: Señales de Alerta | F35: 4 | I35: 10 | K35: 0 | M35: 20

Sheet datos_graficos
A2: FECHA | B2: EVENTO | C2: POSICIÓN | D2: EJE
